Workbook

Sheet Monthly Summary
A1: Dry store Request report
A2: Month
A3: Code | B3: รายการ | C3: Breakfast | D3: Canteen | E3: A la carte | F3: คงเหลือ (Inventory)
C4: (จำนวน) | D4: (จำนวน) | E4: (จำนวน)
A5: 1000005 | B5: เกลือ ปรุงทิพย์ 1000 กรัม | C5: ='วันที่ 1'!E5+'วันที่ 2 '!E5+'วันที่ 3'!E5+'วันที่ 4'!E5+'วันที่ 5'!E5+'วันที่ 6'!E5+'วันที่ 7'!E5+'วันที่ 8'!E5+'วันที่ 9'!E5+'วันที่ 10'!E5+'วันที่11'!E5+'วันที่12'!E5+'วันที่13'!E6+'วันที่ 14'!E5+'วันที่ 15'!E5+'วันที่ 16'!E5+'วันที่ 17'!E5+'วันที่ 18'!E5+'วันที่ 19'!E5+'วันที่ 20'!E5+'วันที่ 21'!E5+'วันที่ 22'!E5+'วันที่ 23'!E5+'วันที่ 24'!E5+'วันที่ 25'!E5+'วันที่ 26'!E5+'วันที่ 27'!E5+'วันที่ 28'!E5+'วันที่ 29'!E5+'วันที่ 30'!E5+'วันที่ 31'!E5 -> 0 | D5: ='วันที่ 1'!F5+'วันที่ 2 '!F5+'วันที่ 3'!F5+'วันที่ 4'!F5+'วันที่ 5'!F5+'วันที่ 6'!F5+'วันที่ 7'!F5+'วันที่ 8'!F5+'วันที่ 9'!F5+'วันที่ 10'!F5+'วันที่11'!F5+'วันที่12'!F5+'วันที่13'!F6+'วันที่ 14'!F5+'วันที่ 15'!F5+'วันที่ 16'!F5+'วันที่ 17'!F5+'วันที่ 18'!F5+'วันที่ 19'!F5+'วันที่ 20'!F5+'วันที่ 21'!F5+'วันที่ 22'!F5+'วันที่ 23'!F5+'วันที่ 24'!F5+'วันที่ 25'!F5+'วันที่ 26'!F5+'วันที่ 27'!F5+'วันที่ 28'!F5+'วันที่ 29'!F5+'วันที่ 30'!F5+'วันที่ 31'!F5 -> 0 | E5: ='วันที่ 1'!G5+'วันที่ 2 '!G5+'วันที่ 3'!G5+'วันที่ 4'!G5+'วันที่ 5'!G5+'วันที่ 6'!G5+'วันที่ 7'!G5+'วันที่ 8'!G5+'วันที่ 9'!G5+'วันที่ 10'!G5+'วันที่11'!G5+'วันที่12'!G5+'วันที่13'!G6+'วันที่ 14'!G5+'วันที่ 15'!G5+'วันที่ 16'!G5+'วันที่ 17'!G5+'วันที่ 18'!G5+'วันที่ 19'!G5+'วันที่ 20'!G5+'วันที่ 21'!G5+'วันที่ 22'!G5+'วันที่ 23'!G5+'วันที่ 24'!G5+'วันที่ 25'!G5+'วันที่ 26'!G5+'วันที่ 27'!G5+'วันที่ 28'!G5+'วันที่ 29'!G5+'วันที่ 30'!G5+'วันที่ 31'!G5 -> 0 | F5: ='วันที่ 31'!K5 -> 8
A6: 1000018 | B6: เต้าเจี้ยวสูตร 1 เด็กสมบูรณ์ 800 มล.*3 | C6: ='วันที่ 1'!E6+'วันที่ 2 '!E6+'วันที่ 3'!E6+'วันที่ 4'!E6+'วันที่ 5'!E6+'วันที่ 6'!E6+'วันที่ 7'!E6+'วันที่ 8'!E6+'วันที่ 9'!E6+'วันที่ 10'!E6+'วันที่11'!E6+'วันที่12'!E6+'วันที่13'!E7+'วันที่ 14'!E6+'วันที่ 15'!E6+'วันที่ 16'!E6+'วันที่ 17'!E6+'วันที่ 18'!E6+'วันที่ 19'!E6+'วันที่ 20'!E6+'วันที่ 21'!E6+'วันที่ 22'!E6+'วันที่ 23'!E6+'วันที่ 24'!E6+'วันที่ 25'!E6+'วันที่ 26'!E6+'วันที่ 27'!E6+'วันที่ 28'!E6+'วันที่ 29'!E6+'วันที่ 30'!E6+'วันที่ 31'!E6 -> 0 | D6: ='วันที่ 1'!F6+'วันที่ 2 '!F6+'วันที่ 3'!F6+'วันที่ 4'!F6+'วันที่ 5'!F6+'วันที่ 6'!F6+'วันที่ 7'!F6+'วันที่ 8'!F6+'วันที่ 9'!F6+'วันที่ 10'!F6+'วันที่11'!F6+'วันที่12'!F6+'วันที่13'!F7+'วันที่ 14'!F6+'วันที่ 15'!F6+'วันที่ 16'!F6+'วันที่ 17'!F6+'วันที่ 18'!F6+'วันที่ 19'!F6+'วันที่ 20'!F6+'วันที่ 21'!F6+'วันที่ 22'!F6+'วันที่ 23'!F6+'วันที่ 24'!F6+'วันที่ 25'!F6+'วันที่ 26'!F6+'วันที่ 27'!F6+'วันที่ 28'!F6+'วันที่ 29'!F6+'วันที่ 30'!F6+'วันที่ 31'!F6 -> 0 | E6: ='วันที่ 1'!G6+'วันที่ 2 '!G6+'วันที่ 3'!G6+'วันที่ 4'!G6+'วันที่ 5'!G6+'วันที่ 6'!G6+'วันที่ 7'!G6+'วันที่ 8'!G6+'วันที่ 9'!G6+'วันที่ 10'!G6+'วันที่11'!G6+'วันที่12'!G6+'วันที่13'!G7+'วันที่ 14'!G6+'วันที่ 15'!G6+'วันที่ 16'!G6+'วันที่ 17'!G6+'วันที่ 18'!G6+'วันที่ 19'!G6+'วันที่ 20'!G6+'วันที่ 21'!G6+'วันที่ 22'!G6+'วันที่ 23'!G6+'วันที่ 24'!G6+'วันที่ 25'!G6+'วันที่ 26'!G6+'วันที่ 27'!G6+'วันที่ 28'!G6+'วันที่ 29'!G6+'วันที่ 30'!G6+'วันที่ 31'!G6 -> 0 | F6: ='วันที่ 31'!K6 -> 1
A7: 1000015 | B7: ซีอิ้วดำสูตร 5 เด็กสมบูรณ์ 940ml. | C7: ='วันที่ 1'!E7+'วันที่ 2 '!E7+'วันที่ 3'!E7+'วันที่ 4'!E7+'วันที่ 5'!E7+'วันที่ 6'!E7+'วันที่ 7'!E7+'วันที่ 8'!E7+'วันที่ 9'!E7+'วันที่ 10'!E7+'วันที่11'!E7+'วันที่12'!E7+'วันที่13'!E8+'วันที่ 14'!E7+'วันที่ 15'!E7+'วันที่ 16'!E7+'วันที่ 17'!E7+'วันที่ 18'!E7+'วันที่ 19'!E7+'วันที่ 20'!E7+'วันที่ 21'!E7+'วันที่ 22'!E7+'วันที่ 23'!E7+'วันที่ 24'!E7+'วันที่ 25'!E7+'วันที่ 26'!E7+'วันที่ 27'!E7+'วันที่ 28'!E7+'วันที่ 29'!E7+'วันที่ 30'!E7+'วันที่ 31'!E7 -> 0 | D7: ='วันที่ 1'!F7+'วันที่ 2 '!F7+'วันที่ 3'!F7+'วันที่ 4'!F7+'วันที่ 5'!F7+'วันที่ 6'!F7+'วันที่ 7'!F7+'วันที่ 8'!F7+'วันที่ 9'!F7+'วันที่ 10'!F7+'วันที่11'!F7+'วันที่12'!F7+'วันที่13'!F8+'วันที่ 14'!F7+'วันที่ 15'!F7+'วันที่ 16'!F7+'วันที่ 17'!F7+'วันที่ 18'!F7+'วันที่ 19'!F7+'วันที่ 20'!F7+'วันที่ 21'!F7+'วันที่ 22'!F7+'วันที่ 23'!F7+'วันที่ 24'!F7+'วันที่ 25'!F7+'วันที่ 26'!F7+'วันที่ 27'!F7+'วันที่ 28'!F7+'วันที่ 29'!F7+'วันที่ 30'!F7+'วันที่ 31'!F7 -> 0 | E7: ='วันที่ 1'!G7+'วันที่ 2 '!G7+'วันที่ 3'!G7+'วันที่ 4'!G7+'วันที่ 5'!G7+'วันที่ 6'!G7+'วันที่ 7'!G7+'วันที่ 8'!G7+'วันที่ 9'!G7+'วันที่ 10'!G7+'วันที่11'!G7+'วันที่12'!G7+'วันที่13'!G8+'วันที่ 14'!G7+'วันที่ 15'!G7+'วันที่ 16'!G7+'วันที่ 17'!G7+'วันที่ 18'!G7+'วันที่ 19'!G7+'วันที่ 20'!G7+'วันที่ 21'!G7+'วันที่ 22'!G7+'วันที่ 23'!G7+'วันที่ 24'!G7+'วันที่ 25'!G7+'วันที่ 26'!G7+'วันที่ 27'!G7+'วันที่ 28'!G7+'วันที่ 29'!G7+'วันที่ 30'!G7+'วันที่ 31'!G7 -> 0 | F7: ='วันที่ 31'!K7 -> 2
A8: 1000025 | B8: น้ำมันน้ำพริกเผา ฉั่วฮะเส็ง 700 ml. | C8: ='วันที่ 1'!E8+'วันที่ 2 '!E8+'วันที่ 3'!E8+'วันที่ 4'!E8+'วันที่ 5'!E8+'วันที่ 6'!E8+'วันที่ 7'!E8+'วันที่ 8'!E8+'วันที่ 9'!E8+'วันที่ 10'!E8+'วันที่11'!E8+'วันที่12'!E8+'วันที่13'!E9+'วันที่ 14'!E8+'วันที่ 15'!E8+'วันที่ 16'!E8+'วันที่ 17'!E8+'วันที่ 18'!E8+'วันที่ 19'!E8+'วันที่ 20'!E8+'วันที่ 21'!E8+'วันที่ 22'!E8+'วันที่ 23'!E8+'วันที่ 24'!E8+'วันที่ 25'!E8+'วันที่ 26'!E8+'วันที่ 27'!E8+'วันที่ 28'!E8+'วันที่ 29'!E8+'วันที่ 30'!E8+'วันที่ 31'!E8 -> 0 | D8: ='วันที่ 1'!F8+'วันที่ 2 '!F8+'วันที่ 3'!F8+'วันที่ 4'!F8+'วันที่ 5'!F8+'วันที่ 6'!F8+'วันที่ 7'!F8+'วันที่ 8'!F8+'วันที่ 9'!F8+'วันที่ 10'!F8+'วันที่11'!F8+'วันที่12'!F8+'วันที่13'!F9+'วันที่ 14'!F8+'วันที่ 15'!F8+'วันที่ 16'!F8+'วันที่ 17'!F8+'วันที่ 18'!F8+'วันที่ 19'!F8+'วันที่ 20'!F8+'วันที่ 21'!F8+'วันที่ 22'!F8+'วันที่ 23'!F8+'วันที่ 24'!F8+'วันที่ 25'!F8+'วันที่ 26'!F8+'วันที่ 27'!F8+'วันที่ 28'!F8+'วันที่ 29'!F8+'วันที่ 30'!F8+'วันที่ 31'!F8 -> 0 | E8: ='วันที่ 1'!G8+'วันที่ 2 '!G8+'วันที่ 3'!G8+'วันที่ 4'!G8+'วันที่ 5'!G8+'วันที่ 6'!G8+'วันที่ 7'!G8+'วันที่ 8'!G8+'วันที่ 9'!G8+'วันที่ 10'!G8+'วันที่11'!G8+'วันที่12'!G8+'วันที่13'!G9+'วันที่ 14'!G8+'วันที่ 15'!G8+'วันที่ 16'!G8+'วันที่ 17'!G8+'วันที่ 18'!G8+'วันที่ 19'!G8+'วันที่ 20'!G8+'วันที่ 21'!G8+'วันที่ 22'!G8+'วันที่ 23'!G8+'วันที่ 24'!G8+'วันที่ 25'!G8+'วันที่ 26'!G8+'วันที่ 27'!G8+'วันที่ 28'!G8+'วันที่ 29'!G8+'วันที่ 30'!G8+'วันที่ 31'!G8 -> 0 | F8: ='วันที่ 31'!K8 -> 3
A9: 1000022 | B9: น้ำพริกเผาฉัวฮะเส็ง 2700g. | C9: ='วันที่ 1'!E9+'วันที่ 2 '!E9+'วันที่ 3'!E9+'วันที่ 4'!E9+'วันที่ 5'!E9+'วันที่ 6'!E9+'วันที่ 7'!E9+'วันที่ 8'!E9+'วันที่ 9'!E9+'วันที่ 10'!E9+'วันที่11'!E9+'วันที่12'!E9+'วันที่13'!E10+'วันที่ 14'!E9+'วันที่ 15'!E9+'วันที่ 16'!E9+'วันที่ 17'!E9+'วันที่ 18'!E9+'วันที่ 19'!E9+'วันที่ 20'!E9+'วันที่ 21'!E9+'วันที่ 22'!E9+'วันที่ 23'!E9+'วันที่ 24'!E9+'วันที่ 25'!E9+'วันที่ 26'!E9+'วันที่ 27'!E9+'วันที่ 28'!E9+'วันที่ 29'!E9+'วันที่ 30'!E9+'วันที่ 31'!E9 -> 0 | D9: ='วันที่ 1'!F9+'วันที่ 2 '!F9+'วันที่ 3'!F9+'วันที่ 4'!F9+'วันที่ 5'!F9+'วันที่ 6'!F9+'วันที่ 7'!F9+'วันที่ 8'!F9+'วันที่ 9'!F9+'วันที่ 10'!F9+'วันที่11'!F9+'วันที่12'!F9+'วันที่13'!F10+'วันที่ 14'!F9+'วันที่ 15'!F9+'วันที่ 16'!F9+'วันที่ 17'!F9+'วันที่ 18'!F9+'วันที่ 19'!F9+'วันที่ 20'!F9+'วันที่ 21'!F9+'วันที่ 22'!F9+'วันที่ 23'!F9+'วันที่ 24'!F9+'วันที่ 25'!F9+'วันที่ 26'!F9+'วันที่ 27'!F9+'วันที่ 28'!F9+'วันที่ 29'!F9+'วันที่ 30'!F9+'วันที่ 31'!F9 -> 0 | E9: ='วันที่ 1'!G9+'วันที่ 2 '!G9+'วันที่ 3'!G9+'วันที่ 4'!G9+'วันที่ 5'!G9+'วันที่ 6'!G9+'วันที่ 7'!G9+'วันที่ 8'!G9+'วันที่ 9'!G9+'วันที่ 10'!G9+'วันที่11'!G9+'วันที่12'!G9+'วันที่13'!G10+'วันที่ 14'!G9+'วันที่ 15'!G9+'วันที่ 16'!G9+'วันที่ 17'!G9+'วันที่ 18'!G9+'วันที่ 19'!G9+'วันที่ 20'!G9+'วันที่ 21'!G9+'วันที่ 22'!G9+'วันที่ 23'!G9+'วันที่ 24'!G9+'วันที่ 25'!G9+'วันที่ 26'!G9+'วันที่ 27'!G9+'วันที่ 28'!G9+'วันที่ 29'!G9+'วันที่ 30'!G9+'วันที่ 31'!G9 -> 0 | F9: ='วันที่ 31'!K9 -> 2
A10: 1000057 | B10: ผงปรุงรส อาหารญี่ปุ่น ฮอนดาชิ 1กก. | C10: ='วันที่ 1'!E10+'วันที่ 2 '!E10+'วันที่ 3'!E10+'วันที่ 4'!E10+'วันที่ 5'!E10+'วันที่ 6'!E10+'วันที่ 7'!E10+'วันที่ 8'!E10+'วันที่ 9'!E10+'วันที่ 10'!E10+'วันที่11'!E10+'วันที่12'!E10+'วันที่13'!E11+'วันที่ 14'!E10+'วันที่ 15'!E10+'วันที่ 16'!E10+'วันที่ 17'!E10+'วันที่ 18'!E10+'วันที่ 19'!E10+'วันที่ 20'!E10+'วันที่ 21'!E10+'วันที่ 22'!E10+'วันที่ 23'!E10+'วันที่ 24'!E10+'วันที่ 25'!E10+'วันที่ 26'!E10+'วันที่ 27'!E10+'วันที่ 28'!E10+'วันที่ 29'!E10+'วันที่ 30'!E10+'วันที่ 31'!E10 -> 0 | D10: ='วันที่ 1'!F10+'วันที่ 2 '!F10+'วันที่ 3'!F10+'วันที่ 4'!F10+'วันที่ 5'!F10+'วันที่ 6'!F10+'วันที่ 7'!F10+'วันที่ 8'!F10+'วันที่ 9'!F10+'วันที่ 10'!F10+'วันที่11'!F10+'วันที่12'!F10+'วันที่13'!F11+'วันที่ 14'!F10+'วันที่ 15'!F10+'วันที่ 16'!F10+'วันที่ 17'!F10+'วันที่ 18'!F10+'วันที่ 19'!F10+'วันที่ 20'!F10+'วันที่ 21'!F10+'วันที่ 22'!F10+'วันที่ 23'!F10+'วันที่ 24'!F10+'วันที่ 25'!F10+'วันที่ 26'!F10+'วันที่ 27'!F10+'วันที่ 28'!F10+'วันที่ 29'!F10+'วันที่ 30'!F10+'วันที่ 31'!F10 -> 0 | E10: ='วันที่ 1'!G10+'วันที่ 2 '!G10+'วันที่ 3'!G10+'วันที่ 4'!G10+'วันที่ 5'!G10+'วันที่ 6'!G10+'วันที่ 7'!G10+'วันที่ 8'!G10+'วันที่ 9'!G10+'วันที่ 10'!G10+'วันที่11'!G10+'วันที่12'!G10+'วันที่13'!G11+'วันที่ 14'!G10+'วันที่ 15'!G10+'วันที่ 16'!G10+'วันที่ 17'!G10+'วันที่ 18'!G10+'วันที่ 19'!G10+'วันที่ 20'!G10+'วันที่ 21'!G10+'วันที่ 22'!G10+'วันที่ 23'!G10+'วันที่ 24'!G10+'วันที่ 25'!G10+'วันที่ 26'!G10+'วันที่ 27'!G10+'วันที่ 28'!G10+'วันที่ 29'!G10+'วันที่ 30'!G10+'วันที่ 31'!G10 -> 0 | F10: ='วันที่ 31'!K10 -> 3
A11: 1000214 | B11: ซอสมะเขือเทศเข้มข้น ตราไมก้า 560 กรัม | C11: ='วันที่ 1'!E11+'วันที่ 2 '!E11+'วันที่ 3'!E11+'วันที่ 4'!E11+'วันที่ 5'!E11+'วันที่ 6'!E11+'วันที่ 7'!E11+'วันที่ 8'!E11+'วันที่ 9'!E11+'วันที่ 10'!E11+'วันที่11'!E11+'วันที่12'!E11+'วันที่13'!E12+'วันที่ 14'!E11+'วันที่ 15'!E11+'วันที่ 16'!E11+'วันที่ 17'!E11+'วันที่ 18'!E11+'วันที่ 19'!E11+'วันที่ 20'!E11+'วันที่ 21'!E11+'วันที่ 22'!E11+'วันที่ 23'!E11+'วันที่ 24'!E11+'วันที่ 25'!E11+'วันที่ 26'!E11+'วันที่ 27'!E11+'วันที่ 28'!E11+'วันที่ 29'!E11+'วันที่ 30'!E11+'วันที่ 31'!E11 -> 0 | D11: ='วันที่ 1'!F11+'วันที่ 2 '!F11+'วันที่ 3'!F11+'วันที่ 4'!F11+'วันที่ 5'!F11+'วันที่ 6'!F11+'วันที่ 7'!F11+'วันที่ 8'!F11+'วันที่ 9'!F11+'วันที่ 10'!F11+'วันที่11'!F11+'วันที่12'!F11+'วันที่13'!F12+'วันที่ 14'!F11+'วันที่ 15'!F11+'วันที่ 16'!F11+'วันที่ 17'!F11+'วันที่ 18'!F11+'วันที่ 19'!F11+'วันที่ 20'!F11+'วันที่ 21'!F11+'วันที่ 22'!F11+'วันที่ 23'!F11+'วันที่ 24'!F11+'วันที่ 25'!F11+'วันที่ 26'!F11+'วันที่ 27'!F11+'วันที่ 28'!F11+'วันที่ 29'!F11+'วันที่ 30'!F11+'วันที่ 31'!F11 -> 0 | E11: ='วันที่ 1'!G11+'วันที่ 2 '!G11+'วันที่ 3'!G11+'วันที่ 4'!G11+'วันที่ 5'!G11+'วันที่ 6'!G11+'วันที่ 7'!G11+'วันที่ 8'!G11+'วันที่ 9'!G11+'วันที่ 10'!G11+'วันที่11'!G11+'วันที่12'!G11+'วันที่13'!G12+'วันที่ 14'!G11+'วันที่ 15'!G11+'วันที่ 16'!G11+'วันที่ 17'!G11+'วันที่ 18'!G11+'วันที่ 19'!G11+'วันที่ 20'!G11+'วันที่ 21'!G11+'วันที่ 22'!G11+'วันที่ 23'!G11+'วันที่ 24'!G11+'วันที่ 25'!G11+'วันที่ 26'!G11+'วันที่ 27'!G11+'วันที่ 28'!G11+'วันที่ 29'!G11+'วันที่ 30'!G11+'วันที่ 31'!G11 -> 0 | F11: ='วันที่ 31'!K11 -> 1
A12: 1010017 | B12: ปลากระป๋อง | C12: ='วันที่ 1'!E12+'วันที่ 2 '!E12+'วันที่ 3'!E12+'วันที่ 4'!E12+'วันที่ 5'!E12+'วันที่ 6'!E12+'วันที่ 7'!E12+'วันที่ 8'!E12+'วันที่ 9'!E12+'วันที่ 10'!E12+'วันที่11'!E12+'วันที่12'!E12+'วันที่13'!E13+'วันที่ 14'!E12+'วันที่ 15'!E12+'วันที่ 16'!E12+'วันที่ 17'!E12+'วันที่ 18'!E12+'วันที่ 19'!E12+'วันที่ 20'!E12+'วันที่ 21'!E12+'วันที่ 22'!E12+'วันที่ 23'!E12+'วันที่ 24'!E12+'วันที่ 25'!E12+'วันที่ 26'!E12+'วันที่ 27'!E12+'วันที่ 28'!E12+'วันที่ 29'!E12+'วันที่ 30'!E12+'วันที่ 31'!E12 -> 0 | D12: ='วันที่ 1'!F12+'วันที่ 2 '!F12+'วันที่ 3'!F12+'วันที่ 4'!F12+'วันที่ 5'!F12+'วันที่ 6'!F12+'วันที่ 7'!F12+'วันที่ 8'!F12+'วันที่ 9'!F12+'วันที่ 10'!F12+'วันที่11'!F12+'วันที่12'!F12+'วันที่13'!F13+'วันที่ 14'!F12+'วันที่ 15'!F12+'วันที่ 16'!F12+'วันที่ 17'!F12+'วันที่ 18'!F12+'วันที่ 19'!F12+'วันที่ 20'!F12+'วันที่ 21'!F12+'วันที่ 22'!F12+'วันที่ 23'!F12+'วันที่ 24'!F12+'วันที่ 25'!F12+'วันที่ 26'!F12+'วันที่ 27'!F12+'วันที่ 28'!F12+'วันที่ 29'!F12+'วันที่ 30'!F12+'วันที่ 31'!F12 -> 0 | E12: ='วันที่ 1'!G12+'วันที่ 2 '!G12+'วันที่ 3'!G12+'วันที่ 4'!G12+'วันที่ 5'!G12+'วันที่ 6'!G12+'วันที่ 7'!G12+'วันที่ 8'!G12+'วันที่ 9'!G12+'วันที่ 10'!G12+'วันที่11'!G12+'วันที่12'!G12+'วันที่13'!G13+'วันที่ 14'!G12+'วันที่ 15'!G12+'วันที่ 16'!G12+'วันที่ 17'!G12+'วันที่ 18'!G12+'วันที่ 19'!G12+'วันที่ 20'!G12+'วันที่ 21'!G12+'วันที่ 22'!G12+'วันที่ 23'!G12+'วันที่ 24'!G12+'วันที่ 25'!G12+'วันที่ 26'!G12+'วันที่ 27'!G12+'วันที่ 28'!G12+'วันที่ 29'!G12+'วันที่ 30'!G12+'วันที่ 31'!G12 -> 0 | F12: ='วันที่ 31'!K12 -> 78
A13: 1010033 | B13: ปลาทูน่าในน้ำมันตราซีเล็คทูน่า 1800 กรัม*1 | C13: ='วันที่ 1'!E13+'วันที่ 2 '!E13+'วันที่ 3'!E13+'วันที่ 4'!E13+'วันที่ 5'!E13+'วันที่ 6'!E13+'วันที่ 7'!E13+'วันที่ 8'!E13+'วันที่ 9'!E13+'วันที่ 10'!E13+'วันที่11'!E13+'วันที่12'!E13+'วันที่13'!E14+'วันที่ 14'!E13+'วันที่ 15'!E13+'วันที่ 16'!E13+'วันที่ 17'!E13+'วันที่ 18'!E13+'วันที่ 19'!E13+'วันที่ 20'!E13+'วันที่ 21'!E13+'วันที่ 22'!E13+'วันที่ 23'!E13+'วันที่ 24'!E13+'วันที่ 25'!E13+'วันที่ 26'!E13+'วันที่ 27'!E13+'วันที่ 28'!E13+'วันที่ 29'!E13+'วันที่ 30'!E13+'วันที่ 31'!E13 -> 0 | D13: ='วันที่ 1'!F13+'วันที่ 2 '!F13+'วันที่ 3'!F13+'วันที่ 4'!F13+'วันที่ 5'!F13+'วันที่ 6'!F13+'วันที่ 7'!F13+'วันที่ 8'!F13+'วันที่ 9'!F13+'วันที่ 10'!F13+'วันที่11'!F13+'วันที่12'!F13+'วันที่13'!F14+'วันที่ 14'!F13+'วันที่ 15'!F13+'วันที่ 16'!F13+'วันที่ 17'!F13+'วันที่ 18'!F13+'วันที่ 19'!F13+'วันที่ 20'!F13+'วันที่ 21'!F13+'วันที่ 22'!F13+'วันที่ 23'!F13+'วันที่ 24'!F13+'วันที่ 25'!F13+'วันที่ 26'!F13+'วันที่ 27'!F13+'วันที่ 28'!F13+'วันที่ 29'!F13+'วันที่ 30'!F13+'วันที่ 31'!F13 -> 0 | E13: ='วันที่ 1'!G13+'วันที่ 2 '!G13+'วันที่ 3'!G13+'วันที่ 4'!G13+'วันที่ 5'!G13+'วันที่ 6'!G13+'วันที่ 7'!G13+'วันที่ 8'!G13+'วันที่ 9'!G13+'วันที่ 10'!G13+'วันที่11'!G13+'วันที่12'!G13+'วันที่13'!G14+'วันที่ 14'!G13+'วันที่ 15'!G13+'วันที่ 16'!G13+'วันที่ 17'!G13+'วันที่ 18'!G13+'วันที่ 19'!G13+'วันที่ 20'!G13+'วันที่ 21'!G13+'วันที่ 22'!G13+'วันที่ 23'!G13+'วันที่ 24'!G13+'วันที่ 25'!G13+'วันที่ 26'!G13+'วันที่ 27'!G13+'วันที่ 28'!G13+'วันที่ 29'!G13+'วันที่ 30'!G13+'วันที่ 31'!G13 -> 0 | F13: ='วันที่ 31'!K13 -> 4
A14: 1050003 | B14: น้ำตาลทรายขาวมิตรผล 1 กก.*ถุง | C14: ='วันที่ 1'!E14+'วันที่ 2 '!E14+'วันที่ 3'!E14+'วันที่ 4'!E14+'วันที่ 5'!E14+'วันที่ 6'!E14+'วันที่ 7'!E14+'วันที่ 8'!E14+'วันที่ 9'!E14+'วันที่ 10'!E14+'วันที่11'!E14+'วันที่12'!E14+'วันที่13'!E15+'วันที่ 14'!E14+'วันที่ 15'!E14+'วันที่ 16'!E14+'วันที่ 17'!E14+'วันที่ 18'!E14+'วันที่ 19'!E14+'วันที่ 20'!E14+'วันที่ 21'!E14+'วันที่ 22'!E14+'วันที่ 23'!E14+'วันที่ 24'!E14+'วันที่ 25'!E14+'วันที่ 26'!E14+'วันที่ 27'!E14+'วันที่ 28'!E14+'วันที่ 29'!E14+'วันที่ 30'!E14+'วันที่ 31'!E14 -> 0 | D14: ='วันที่ 1'!F14+'วันที่ 2 '!F14+'วันที่ 3'!F14+'วันที่ 4'!F14+'วันที่ 5'!F14+'วันที่ 6'!F14+'วันที่ 7'!F14+'วันที่ 8'!F14+'วันที่ 9'!F14+'วันที่ 10'!F14+'วันที่11'!F14+'วันที่12'!F14+'วันที่13'!F15+'วันที่ 14'!F14+'วันที่ 15'!F14+'วันที่ 16'!F14+'วันที่ 17'!F14+'วันที่ 18'!F14+'วันที่ 19'!F14+'วันที่ 20'!F14+'วันที่ 21'!F14+'วันที่ 22'!F14+'วันที่ 23'!F14+'วันที่ 24'!F14+'วันที่ 25'!F14+'วันที่ 26'!F14+'วันที่ 27'!F14+'วันที่ 28'!F14+'วันที่ 29'!F14+'วันที่ 30'!F14+'วันที่ 31'!F14 -> 0 | E14: ='วันที่ 1'!G14+'วันที่ 2 '!G14+'วันที่ 3'!G14+'วันที่ 4'!G14+'วันที่ 5'!G14+'วันที่ 6'!G14+'วันที่ 7'!G14+'วันที่ 8'!G14+'วันที่ 9'!G14+'วันที่ 10'!G14+'วันที่11'!G14+'วันที่12'!G14+'วันที่13'!G15+'วันที่ 14'!G14+'วันที่ 15'!G14+'วันที่ 16'!G14+'วันที่ 17'!G14+'วันที่ 18'!G14+'วันที่ 19'!G14+'วันที่ 20'!G14+'วันที่ 21'!G14+'วันที่ 22'!G14+'วันที่ 23'!G14+'วันที่ 24'!G14+'วันที่ 25'!G14+'วันที่ 26'!G14+'วันที่ 27'!G14+'วันที่ 28'!G14+'วันที่ 29'!G14+'วันที่ 30'!G14+'วันที่ 31'!G14 -> 0 | F14: ='วันที่ 31'!K14 -> 63
A15: 1050037 | B15: น้ำตาลอ้อยผสมน้ำตาลมะพร้าว มิตรผล 1กก*ถุง | C15: ='วันที่ 1'!E15+'วันที่ 2 '!E15+'วันที่ 3'!E15+'วันที่ 4'!E15+'วันที่ 5'!E15+'วันที่ 6'!E15+'วันที่ 7'!E15+'วันที่ 8'!E15+'วันที่ 9'!E15+'วันที่ 10'!E15+'วันที่11'!E15+'วันที่12'!E15+'วันที่13'!E16+'วันที่ 14'!E15+'วันที่ 15'!E15+'วันที่ 16'!E15+'วันที่ 17'!E15+'วันที่ 18'!E15+'วันที่ 19'!E15+'วันที่ 20'!E15+'วันที่ 21'!E15+'วันที่ 22'!E15+'วันที่ 23'!E15+'วันที่ 24'!E15+'วันที่ 25'!E15+'วันที่ 26'!E15+'วันที่ 27'!E15+'วันที่ 28'!E15+'วันที่ 29'!E15+'วันที่ 30'!E15+'วันที่ 31'!E15 -> 0 | D15: ='วันที่ 1'!F15+'วันที่ 2 '!F15+'วันที่ 3'!F15+'วันที่ 4'!F15+'วันที่ 5'!F15+'วันที่ 6'!F15+'วันที่ 7'!F15+'วันที่ 8'!F15+'วันที่ 9'!F15+'วันที่ 10'!F15+'วันที่11'!F15+'วันที่12'!F15+'วันที่13'!F16+'วันที่ 14'!F15+'วันที่ 15'!F15+'วันที่ 16'!F15+'วันที่ 17'!F15+'วันที่ 18'!F15+'วันที่ 19'!F15+'วันที่ 20'!F15+'วันที่ 21'!F15+'วันที่ 22'!F15+'วันที่ 23'!F15+'วันที่ 24'!F15+'วันที่ 25'!F15+'วันที่ 26'!F15+'วันที่ 27'!F15+'วันที่ 28'!F15+'วันที่ 29'!F15+'วันที่ 30'!F15+'วันที่ 31'!F15 -> 0 | E15: ='วันที่ 1'!G15+'วันที่ 2 '!G15+'วันที่ 3'!G15+'วันที่ 4'!G15+'วันที่ 5'!G15+'วันที่ 6'!G15+'วันที่ 7'!G15+'วันที่ 8'!G15+'วันที่ 9'!G15+'วันที่ 10'!G15+'วันที่11'!G15+'วันที่12'!G15+'วันที่13'!G16+'วันที่ 14'!G15+'วันที่ 15'!G15+'วันที่ 16'!G15+'วันที่ 17'!G15+'วันที่ 18'!G15+'วันที่ 19'!G15+'วันที่ 20'!G15+'วันที่ 21'!G15+'วันที่ 22'!G15+'วันที่ 23'!G15+'วันที่ 24'!G15+'วันที่ 25'!G15+'วันที่ 26'!G15+'วันที่ 27'!G15+'วันที่ 28'!G15+'วันที่ 29'!G15+'วันที่ 30'!G15+'วันที่ 31'!G15 -> 1 | F15: ='วันที่ 31'!K15 -> 18
A16: 1380073 | B16: เอโร่ แป้งข้าวโพด 1 กก. | C16: ='วันที่ 1'!E16+'วันที่ 2 '!E16+'วันที่ 3'!E16+'วันที่ 4'!E16+'วันที่ 5'!E16+'วันที่ 6'!E16+'วันที่ 7'!E16+'วันที่ 8'!E16+'วันที่ 9'!E16+'วันที่ 10'!E16+'วันที่11'!E16+'วันที่12'!E16+'วันที่13'!E17+'วันที่ 14'!E16+'วันที่ 15'!E16+'วันที่ 16'!E16+'วันที่ 17'!E16+'วันที่ 18'!E16+'วันที่ 19'!E16+'วันที่ 20'!E16+'วันที่ 21'!E16+'วันที่ 22'!E16+'วันที่ 23'!E16+'วันที่ 24'!E16+'วันที่ 25'!E16+'วันที่ 26'!E16+'วันที่ 27'!E16+'วันที่ 28'!E16+'วันที่ 29'!E16+'วันที่ 30'!E16+'วันที่ 31'!E16 -> 0 | D16: ='วันที่ 1'!F16+'วันที่ 2 '!F16+'วันที่ 3'!F16+'วันที่ 4'!F16+'วันที่ 5'!F16+'วันที่ 6'!F16+'วันที่ 7'!F16+'วันที่ 8'!F16+'วันที่ 9'!F16+'วันที่ 10'!F16+'วันที่11'!F16+'วันที่12'!F16+'วันที่13'!F17+'วันที่ 14'!F16+'วันที่ 15'!F16+'วันที่ 16'!F16+'วันที่ 17'!F16+'วันที่ 18'!F16+'วันที่ 19'!F16+'วันที่ 20'!F16+'วันที่ 21'!F16+'วันที่ 22'!F16+'วันที่ 23'!F16+'วันที่ 24'!F16+'วันที่ 25'!F16+'วันที่ 26'!F16+'วันที่ 27'!F16+'วันที่ 28'!F16+'วันที่ 29'!F16+'วันที่ 30'!F16+'วันที่ 31'!F16 -> 0 | E16: ='วันที่ 1'!G16+'วันที่ 2 '!G16+'วันที่ 3'!G16+'วันที่ 4'!G16+'วันที่ 5'!G16+'วันที่ 6'!G16+'วันที่ 7'!G16+'วันที่ 8'!G16+'วันที่ 9'!G16+'วันที่ 10'!G16+'วันที่11'!G16+'วันที่12'!G16+'วันที่13'!G17+'วันที่ 14'!G16+'วันที่ 15'!G16+'วันที่ 16'!G16+'วันที่ 17'!G16+'วันที่ 18'!G16+'วันที่ 19'!G16+'วันที่ 20'!G16+'วันที่ 21'!G16+'วันที่ 22'!G16+'วันที่ 23'!G16+'วันที่ 24'!G16+'วันที่ 25'!G16+'วันที่ 26'!G16+'วันที่ 27'!G16+'วันที่ 28'!G16+'วันที่ 29'!G16+'วันที่ 30'!G16+'วันที่ 31'!G16 -> 0 | F16: ='วันที่ 31'!K16 -> 1
... A34: 1110009 | B34: โบนัส น้ำมันปาล์ม ถัง 18 ล. | C34: ='วันที่ 1'!E34+'วันที่ 2 '!E34+'วันที่ 3'!E34+'วันที่ 4'!E34+'วันที่ 5'!E34+'วันที่ 6'!E34+'วันที่ 7'!E34+'วันที่ 8'!E34+'วันที่ 9'!E34+'วันที่ 10'!E34+'วันที่11'!E34+'วันที่12'!E34+'วันที่13'!E35+'วันที่ 14'!E34+'วันที่ 15'!E34+'วันที่ 16'!E34+'วันที่ 17'!E34+'วันที่ 18'!E34+'วันที่ 19'!E34+'วันที่ 20'!E34+'วันที่ 21'!E34+'วันที่ 22'!E34+'วันที่ 23'!E34+'วันที่ 24'!E34+'วันที่ 25'!E34+'วันที่ 26'!E34+'วันที่ 27'!E34+'วันที่ 28'!E34+'วันที่ 29'!E34+'วันที่ 30'!E34+'วันที่ 31'!E34 -> 0 | D34: ='วันที่ 1'!F34+'วันที่ 2 '!F34+'วันที่ 3'!F34+'วันที่ 4'!F34+'วันที่ 5'!F34+'วันที่ 6'!F34+'วันที่ 7'!F34+'วันที่ 8'!F34+'วันที่ 9'!F34+'วันที่ 10'!F34+'วันที่11'!F34+'วันที่12'!F34+'วันที่13'!F35+'วันที่ 14'!F34+'วันที่ 15'!F34+'วันที่ 16'!F34+'วันที่ 17'!F34+'วันที่ 18'!F34+'วันที่ 19'!F34+'วันที่ 20'!F34+'วันที่ 21'!F34+'วันที่ 22'!F34+'วันที่ 23'!F34+'วันที่ 24'!F34+'วันที่ 25'!F34+'วันที่ 26'!F34+'วันที่ 27'!F34+'วันที่ 28'!F34+'วันที่ 29'!F34+'วันที่ 30'!F34+'วันที่ 31'!F34 -> 0 | E34: ='วันที่ 1'!G34+'วันที่ 2 '!G34+'วันที่ 3'!G34+'วันที่ 4'!G34+'วันที่ 5'!G34+'วันที่ 6'!G34+'วันที่ 7'!G34+'วันที่ 8'!G34+'วันที่ 9'!G34+'วันที่ 10'!G34+'วันที่11'!G34+'วันที่12'!G34+'วันที่13'!G35+'วันที่ 14'!G34+'วันที่ 15'!G34+'วันที่ 16'!G34+'วันที่ 17'!G34+'วันที่ 18'!G34+'วันที่ 19'!G34+'วันที่ 20'!G34+'วันที่ 21'!G34+'วันที่ 22'!G34+'วันที่ 23'!G34+'วันที่ 24'!G34+'วันที่ 25'!G34+'วันที่ 26'!G34+'วันที่ 27'!G34+'วันที่ 28'!G34+'วันที่ 29'!G34+'วันที่ 30'!G34+'วันที่ 31'!G34 -> 1 | F34: ='วันที่ 31'!K34 -> 3
A35: 1500271 | B35: มายองเนส ตราเอโร่ 1000 กรัม*1 | C35: ='วันที่ 1'!E36+'วันที่ 2 '!E35+'วันที่ 3'!E35+'วันที่ 4'!E35+'วันที่ 5'!E35+'วันที่ 6'!E35+'วันที่ 7'!E35+'วันที่ 8'!E35+'วันที่ 9'!E35+'วันที่ 10'!E35+'วันที่11'!E35+'วันที่12'!E35+'วันที่13'!E36+'วันที่ 14'!E35+'วันที่ 15'!E35+'วันที่ 16'!E35+'วันที่ 17'!E35+'วันที่ 18'!E35+'วันที่ 19'!E35+'วันที่ 20'!E35+'วันที่ 21'!E35+'วันที่ 22'!E35+'วันที่ 23'!E35+'วันที่ 24'!E35+'วันที่ 25'!E35+'วันที่ 26'!E35+'วันที่ 27'!E35+'วันที่ 28'!E35+'วันที่ 29'!E35+'วันที่ 30'!E35+'วันที่ 31'!E35 -> 0 | D35: ='วันที่ 1'!F36+'วันที่ 2 '!F35+'วันที่ 3'!F35+'วันที่ 4'!F35+'วันที่ 5'!F35+'วันที่ 6'!F35+'วันที่ 7'!F35+'วันที่ 8'!F35+'วันที่ 9'!F35+'วันที่ 10'!F35+'วันที่11'!F35+'วันที่12'!F35+'วันที่13'!F36+'วันที่ 14'!F35+'วันที่ 15'!F35+'วันที่ 16'!F35+'วันที่ 17'!F35+'วันที่ 18'!F35+'วันที่ 19'!F35+'วันที่ 20'!F35+'วันที่ 21'!F35+'วันที่ 22'!F35+'วันที่ 23'!F35+'วันที่ 24'!F35+'วันที่ 25'!F35+'วันที่ 26'!F35+'วันที่ 27'!F35+'วันที่ 28'!F35+'วันที่ 29'!F35+'วันที่ 30'!F35+'วันที่ 31'!F35 -> 0 | E35: ='วันที่ 1'!G36+'วันที่ 2 '!G35+'วันที่ 3'!G35+'วันที่ 4'!G35+'วันที่ 5'!G35+'วันที่ 6'!G35+'วันที่ 7'!G35+'วันที่ 8'!G35+'วันที่ 9'!G35+'วันที่ 10'!G35+'วันที่11'!G35+'วันที่12'!G35+'วันที่13'!G36+'วันที่ 14'!G35+'วันที่ 15'!G35+'วันที่ 16'!G35+'วันที่ 17'!G35+'วันที่ 18'!G35+'วันที่ 19'!G35+'วันที่ 20'!G35+'วันที่ 21'!G35+'วันที่ 22'!G35+'วันที่ 23'!G35+'วันที่ 24'!G35+'วันที่ 25'!G35+'วันที่ 26'!G35+'วันที่ 27'!G35+'วันที่ 28'!G35+'วันที่ 29'!G35+'วันที่ 30'!G35+'วันที่ 31'!G35 -> 0 | F35: ='วันที่ 31'!K35 -> 9
A36: 1500052 | B36: มายองเนส (เรียล) เบสท์ฟูดส์ 1กก*ถุง (อะราคาส) | C36: ='วันที่ 1'!E36+'วันที่ 2 '!E35+'วันที่ 3'!E35+'วันที่ 4'!E35+'วันที่ 5'!E35+'วันที่ 6'!E35+'วันที่ 7'!E35+'วันที่ 8'!E35+'วันที่ 9'!E35+'วันที่ 10'!E35+'วันที่11'!E35+'วันที่12'!E35+'วันที่13'!E36+'วันที่ 14'!E35+'วันที่ 15'!E35+'วันที่ 16'!E35+'วันที่ 17'!E35+'วันที่ 18'!E35+'วันที่ 19'!E35+'วันที่ 20'!E35+'วันที่ 21'!E35+'วันที่ 22'!E35+'วันที่ 23'!E35+'วันที่ 24'!E35+'วันที่ 25'!E35+'วันที่ 26'!E35+'วันที่ 27'!E35+'วันที่ 28'!E35+'วันที่ 29'!E35+'วันที่ 30'!E35+'วันที่ 31'!E35 -> 0 | D36: ='วันที่ 1'!F36+'วันที่ 2 '!F35+'วันที่ 3'!F35+'วันที่ 4'!F35+'วันที่ 5'!F35+'วันที่ 6'!F35+'วันที่ 7'!F35+'วันที่ 8'!F35+'วันที่ 9'!F35+'วันที่ 10'!F35+'วันที่11'!F35+'วันที่12'!F35+'วันที่13'!F36+'วันที่ 14'!F35+'วันที่ 15'!F35+'วันที่ 16'!F35+'วันที่ 17'!F35+'วันที่ 18'!F35+'วันที่ 19'!F35+'วันที่ 20'!F35+'วันที่ 21'!F35+'วันที่ 22'!F35+'วันที่ 23'!F35+'วันที่ 24'!F35+'วันที่ 25'!F35+'วันที่ 26'!F35+'วันที่ 27'!F35+'วันที่ 28'!F35+'วันที่ 29'!F35+'วันที่ 30'!F35+'วันที่ 31'!F35 -> 0 | E36: ='วันที่ 1'!G36+'วันที่ 2 '!G35+'วันที่ 3'!G35+'วันที่ 4'!G35+'วันที่ 5'!G35+'วันที่ 6'!G35+'วันที่ 7'!G35+'วันที่ 8'!G35+'วันที่ 9'!G35+'วันที่ 10'!G35+'วันที่11'!G35+'วันที่12'!G35+'วันที่13'!G36+'วันที่ 14'!G35+'วันที่ 15'!G35+'วันที่ 16'!G35+'วันที่ 17'!G35+'วันที่ 18'!G35+'วันที่ 19'!G35+'วันที่ 20'!G35+'วันที่ 21'!G35+'วันที่ 22'!G35+'วันที่ 23'!G35+'วันที่ 24'!G35+'วันที่ 25'!G35+'วันที่ 26'!G35+'วันที่ 27'!G35+'วันที่ 28'!G35+'วันที่ 29'!G35+'วันที่ 30'!G35+'วันที่ 31'!G35 -> 0 | F36: ='วันที่ 31'!K35 -> 9
A37: 1500272 | B37: น้ำสลัดเทาซัน ไอน์แลนด์ 1กก.*ถุง | C37: ='วันที่ 1'!E37+'วันที่ 2 '!E36+'วันที่ 3'!E36+'วันที่ 4'!E36+'วันที่ 5'!E36+'วันที่ 6'!E36+'วันที่ 7'!E36+'วันที่ 8'!E36+'วันที่ 9'!E36+'วันที่ 10'!E36+'วันที่11'!E36+'วันที่12'!E36+'วันที่13'!E37+'วันที่ 14'!E36+'วันที่ 15'!E36+'วันที่ 16'!E36+'วันที่ 17'!E36+'วันที่ 18'!E36+'วันที่ 19'!E36+'วันที่ 20'!E36+'วันที่ 21'!E36+'วันที่ 22'!E36+'วันที่ 23'!E36+'วันที่ 24'!E36+'วันที่ 25'!E36+'วันที่ 26'!E36+'วันที่ 27'!E36+'วันที่ 28'!E36+'วันที่ 29'!E36+'วันที่ 30'!E36+'วันที่ 31'!E36 -> 0 | D37: ='วันที่ 1'!F37+'วันที่ 2 '!F36+'วันที่ 3'!F36+'วันที่ 4'!F36+'วันที่ 5'!F36+'วันที่ 6'!F36+'วันที่ 7'!F36+'วันที่ 8'!F36+'วันที่ 9'!F36+'วันที่ 10'!F36+'วันที่11'!F36+'วันที่12'!F36+'วันที่13'!F37+'วันที่ 14'!F36+'วันที่ 15'!F36+'วันที่ 16'!F36+'วันที่ 17'!F36+'วันที่ 18'!F36+'วันที่ 19'!F36+'วันที่ 20'!F36+'วันที่ 21'!F36+'วันที่ 22'!F36+'วันที่ 23'!F36+'วันที่ 24'!F36+'วันที่ 25'!F36+'วันที่ 26'!F36+'วันที่ 27'!F36+'วันที่ 28'!F36+'วันที่ 29'!F36+'วันที่ 30'!F36+'วันที่ 31'!F36 -> 0 | E37: ='วันที่ 1'!G37+'วันที่ 2 '!G36+'วันที่ 3'!G36+'วันที่ 4'!G36+'วันที่ 5'!G36+'วันที่ 6'!G36+'วันที่ 7'!G36+'วันที่ 8'!G36+'วันที่ 9'!G36+'วันที่ 10'!G36+'วันที่11'!G36+'วันที่12'!G36+'วันที่13'!G37+'วันที่ 14'!G36+'วันที่ 15'!G36+'วันที่ 16'!G36+'วันที่ 17'!G36+'วันที่ 18'!G36+'วันที่ 19'!G36+'วันที่ 20'!G36+'วันที่ 21'!G36+'วันที่ 22'!G36+'วันที่ 23'!G36+'วันที่ 24'!G36+'วันที่ 25'!G36+'วันที่ 26'!G36+'วันที่ 27'!G36+'วันที่ 28'!G36+'วันที่ 29'!G36+'วันที่ 30'!G36+'วันที่ 31'!G36 -> 0 | F37: ='วันที่ 31'!K36 -> 7
A38: 1120026 | B38: เนยถั่วแบบบดละเอียด ตราจิฟ 454 ก. | C38: ='วันที่ 1'!E38+'วันที่ 2 '!E37+'วันที่ 3'!E37+'วันที่ 4'!E37+'วันที่ 5'!E37+'วันที่ 6'!E37+'วันที่ 7'!E37+'วันที่ 8'!E37+'วันที่ 9'!E37+'วันที่ 10'!E37+'วันที่11'!E37+'วันที่12'!E37+'วันที่13'!E38+'วันที่ 14'!E37+'วันที่ 15'!E37+'วันที่ 16'!E37+'วันที่ 17'!E37+'วันที่ 18'!E37+'วันที่ 19'!E37+'วันที่ 20'!E37+'วันที่ 21'!E37+'วันที่ 22'!E37+'วันที่ 23'!E37+'วันที่ 24'!E37+'วันที่ 25'!E37+'วันที่ 26'!E37+'วันที่ 27'!E37+'วันที่ 28'!E37+'วันที่ 29'!E37+'วันที่ 30'!E37+'วันที่ 31'!E37 -> 0 | D38: ='วันที่ 1'!F38+'วันที่ 2 '!F37+'วันที่ 3'!F37+'วันที่ 4'!F37+'วันที่ 5'!F37+'วันที่ 6'!F37+'วันที่ 7'!F37+'วันที่ 8'!F37+'วันที่ 9'!F37+'วันที่ 10'!F37+'วันที่11'!F37+'วันที่12'!F37+'วันที่13'!F38+'วันที่ 14'!F37+'วันที่ 15'!F37+'วันที่ 16'!F37+'วันที่ 17'!F37+'วันที่ 18'!F37+'วันที่ 19'!F37+'วันที่ 20'!F37+'วันที่ 21'!F37+'วันที่ 22'!F37+'วันที่ 23'!F37+'วันที่ 24'!F37+'วันที่ 25'!F37+'วันที่ 26'!F37+'วันที่ 27'!F37+'วันที่ 28'!F37+'วันที่ 29'!F37+'วันที่ 30'!F37+'วันที่ 31'!F37 -> 0 | E38: ='วันที่ 1'!G38+'วันที่ 2 '!G37+'วันที่ 3'!G37+'วันที่ 4'!G37+'วันที่ 5'!G37+'วันที่ 6'!G37+'วันที่ 7'!G37+'วันที่ 8'!G37+'วันที่ 9'!G37+'วันที่ 10'!G37+'วันที่11'!G37+'วันที่12'!G37+'วันที่13'!G38+'วันที่ 14'!G37+'วันที่ 15'!G37+'วันที่ 16'!G37+'วันที่ 17'!G37+'วันที่ 18'!G37+'วันที่ 19'!G37+'วันที่ 20'!G37+'วันที่ 21'!G37+'วันที่ 22'!G37+'วันที่ 23'!G37+'วันที่ 24'!G37+'วันที่ 25'!G37+'วันที่ 26'!G37+'วันที่ 27'!G37+'วันที่ 28'!G37+'วันที่ 29'!G37+'วันที่ 30'!G37+'วันที่ 31'!G37 -> 0 | F38: ='วันที่ 31'!K37 -> 6
A39: 1000001 | B39: ถั่วขาวในซอสมะเขือเทศ 425 g. | C39: ='วันที่ 1'!E39+'วันที่ 2 '!E38+'วันที่ 3'!E38+'วันที่ 4'!E38+'วันที่ 5'!E38+'วันที่ 6'!E38+'วันที่ 7'!E38+'วันที่ 8'!E38+'วันที่ 9'!E38+'วันที่ 10'!E38+'วันที่11'!E38+'วันที่12'!E38+'วันที่13'!E39+'วันที่ 14'!E38+'วันที่ 15'!E38+'วันที่ 16'!E38+'วันที่ 17'!E38+'วันที่ 18'!E38+'วันที่ 19'!E38+'วันที่ 20'!E38+'วันที่ 21'!E38+'วันที่ 22'!E38+'วันที่ 23'!E38+'วันที่ 24'!E38+'วันที่ 25'!E38+'วันที่ 26'!E38+'วันที่ 27'!E38+'วันที่ 28'!E38+'วันที่ 29'!E38+'วันที่ 30'!E38+'วันที่ 31'!E38 -> 0 | D39: ='วันที่ 1'!F39+'วันที่ 2 '!F38+'วันที่ 3'!F38+'วันที่ 4'!F38+'วันที่ 5'!F38+'วันที่ 6'!F38+'วันที่ 7'!F38+'วันที่ 8'!F38+'วันที่ 9'!F38+'วันที่ 10'!F38+'วันที่11'!F38+'วันที่12'!F38+'วันที่13'!F39+'วันที่ 14'!F38+'วันที่ 15'!F38+'วันที่ 16'!F38+'วันที่ 17'!F38+'วันที่ 18'!F38+'วันที่ 19'!F38+'วันที่ 20'!F38+'วันที่ 21'!F38+'วันที่ 22'!F38+'วันที่ 23'!F38+'วันที่ 24'!F38+'วันที่ 25'!F38+'วันที่ 26'!F38+'วันที่ 27'!F38+'วันที่ 28'!F38+'วันที่ 29'!F38+'วันที่ 30'!F38+'วันที่ 31'!F38 -> 0 | E39: ='วันที่ 1'!G39+'วันที่ 2 '!G38+'วันที่ 3'!G38+'วันที่ 4'!G38+'วันที่ 5'!G38+'วันที่ 6'!G38+'วันที่ 7'!G38+'วันที่ 8'!G38+'วันที่ 9'!G38+'วันที่ 10'!G38+'วันที่11'!G38+'วันที่12'!G38+'วันที่13'!G39+'วันที่ 14'!G38+'วันที่ 15'!G38+'วันที่ 16'!G38+'วันที่ 17'!G38+'วันที่ 18'!G38+'วันที่ 19'!G38+'วันที่ 20'!G38+'วันที่ 21'!G38+'วันที่ 22'!G38+'วันที่ 23'!G38+'วันที่ 24'!G38+'วันที่ 25'!G38+'วันที่ 26'!G38+'วันที่ 27'!G38+'วันที่ 28'!G38+'วันที่ 29'!G38+'วันที่ 30'!G38+'วันที่ 31'!G38 -> 0 | F39: ='วันที่ 31'!K38 -> 10
A40: 1000019 | B40: น้ำปรุงรสข้าวซูชิ เอโร่ 1 ลิตร | C40: ='วันที่ 1'!E40+'วันที่ 2 '!E39+'วันที่ 3'!E39+'วันที่ 4'!E39+'วันที่ 5'!E39+'วันที่ 6'!E39+'วันที่ 7'!E39+'วันที่ 8'!E39+'วันที่ 9'!E39+'วันที่ 10'!E39+'วันที่11'!E39+'วันที่12'!E39+'วันที่13'!E40+'วันที่ 14'!E39+'วันที่ 15'!E39+'วันที่ 16'!E39+'วันที่ 17'!E39+'วันที่ 18'!E39+'วันที่ 19'!E39+'วันที่ 20'!E39+'วันที่ 21'!E39+'วันที่ 22'!E39+'วันที่ 23'!E39+'วันที่ 24'!E39+'วันที่ 25'!E39+'วันที่ 26'!E39+'วันที่ 27'!E39+'วันที่ 28'!E39+'วันที่ 29'!E39+'วันที่ 30'!E39+'วันที่ 31'!E39 -> 0 | D40: ='วันที่ 1'!F40+'วันที่ 2 '!F39+'วันที่ 3'!F39+'วันที่ 4'!F39+'วันที่ 5'!F39+'วันที่ 6'!F39+'วันที่ 7'!F39+'วันที่ 8'!F39+'วันที่ 9'!F39+'วันที่ 10'!F39+'วันที่11'!F39+'วันที่12'!F39+'วันที่13'!F40+'วันที่ 14'!F39+'วันที่ 15'!F39+'วันที่ 16'!F39+'วันที่ 17'!F39+'วันที่ 18'!F39+'วันที่ 19'!F39+'วันที่ 20'!F39+'วันที่ 21'!F39+'วันที่ 22'!F39+'วันที่ 23'!F39+'วันที่ 24'!F39+'วันที่ 25'!F39+'วันที่ 26'!F39+'วันที่ 27'!F39+'วันที่ 28'!F39+'วันที่ 29'!F39+'วันที่ 30'!F39+'วันที่ 31'!F39 -> 0 | E40: ='วันที่ 1'!G40+'วันที่ 2 '!G39+'วันที่ 3'!G39+'วันที่ 4'!G39+'วันที่ 5'!G39+'วันที่ 6'!G39+'วันที่ 7'!G39+'วันที่ 8'!G39+'วันที่ 9'!G39+'วันที่ 10'!G39+'วันที่11'!G39+'วันที่12'!G39+'วันที่13'!G40+'วันที่ 14'!G39+'วันที่ 15'!G39+'วันที่ 16'!G39+'วันที่ 17'!G39+'วันที่ 18'!G39+'วันที่ 19'!G39+'วันที่ 20'!G39+'วันที่ 21'!G39+'วันที่ 22'!G39+'วันที่ 23'!G39+'วันที่ 24'!G39+'วันที่ 25'!G39+'วันที่ 26'!G39+'วันที่ 27'!G39+'วันที่ 28'!G39+'วันที่ 29'!G39+'วันที่ 30'!G39+'วันที่ 31'!G39 -> 0 | F40: ='วันที่ 31'!K39 -> 5
A41: 1000062 | B41: ผงปาปริก้า (PAPRIKA) ตราแม็คคอร์มิค 510g.*กระปุก | C41: ='วันที่ 1'!E41+'วันที่ 2 '!E40+'วันที่ 3'!E40+'วันที่ 4'!E40+'วันที่ 5'!E40+'วันที่ 6'!E40+'วันที่ 7'!E40+'วันที่ 8'!E40+'วันที่ 9'!E40+'วันที่ 10'!E40+'วันที่11'!E40+'วันที่12'!E40+'วันที่13'!E41+'วันที่ 14'!E40+'วันที่ 15'!E40+'วันที่ 16'!E40+'วันที่ 17'!E40+'วันที่ 18'!E40+'วันที่ 19'!E40+'วันที่ 20'!E40+'วันที่ 21'!E40+'วันที่ 22'!E40+'วันที่ 23'!E40+'วันที่ 24'!E40+'วันที่ 25'!E40+'วันที่ 26'!E40+'วันที่ 27'!E40+'วันที่ 28'!E40+'วันที่ 29'!E40+'วันที่ 30'!E40+'วันที่ 31'!E40 -> 0 | D41: ='วันที่ 1'!F41+'วันที่ 2 '!F40+'วันที่ 3'!F40+'วันที่ 4'!F40+'วันที่ 5'!F40+'วันที่ 6'!F40+'วันที่ 7'!F40+'วันที่ 8'!F40+'วันที่ 9'!F40+'วันที่ 10'!F40+'วันที่11'!F40+'วันที่12'!F40+'วันที่13'!F41+'วันที่ 14'!F40+'วันที่ 15'!F40+'วันที่ 16'!F40+'วันที่ 17'!F40+'วันที่ 18'!F40+'วันที่ 19'!F40+'วันที่ 20'!F40+'วันที่ 21'!F40+'วันที่ 22'!F40+'วันที่ 23'!F40+'วันที่ 24'!F40+'วันที่ 25'!F40+'วันที่ 26'!F40+'วันที่ 27'!F40+'วันที่ 28'!F40+'วันที่ 29'!F40+'วันที่ 30'!F40+'วันที่ 31'!F40 -> 0 | E41: ='วันที่ 1'!G41+'วันที่ 2 '!G40+'วันที่ 3'!G40+'วันที่ 4'!G40+'วันที่ 5'!G40+'วันที่ 6'!G40+'วันที่ 7'!G40+'วันที่ 8'!G40+'วันที่ 9'!G40+'วันที่ 10'!G40+'วันที่11'!G40+'วันที่12'!G40+'วันที่13'!G41+'วันที่ 14'!G40+'วันที่ 15'!G40+'วันที่ 16'!G40+'วันที่ 17'!G40+'วันที่ 18'!G40+'วันที่ 19'!G40+'วันที่ 20'!G40+'วันที่ 21'!G40+'วันที่ 22'!G40+'วันที่ 23'!G40+'วันที่ 24'!G40+'วันที่ 25'!G40+'วันที่ 26'!G40+'วันที่ 27'!G40+'วันที่ 28'!G40+'วันที่ 29'!G40+'วันที่ 30'!G40+'วันที่ 31'!G40 -> 0 | F41: ='วันที่ 31'!K40 -> 4
A43: 1000083 | B43: น้ำส้มสายชูไวน์ขาว ตรา แบร์ทอลลี ขนาด 500 ml. | C43: ='วันที่ 1'!E43+'วันที่ 2 '!E42+'วันที่ 3'!E42+'วันที่ 4'!E42+'วันที่ 5'!E42+'วันที่ 6'!E42+'วันที่ 7'!E42+'วันที่ 8'!E42+'วันที่ 9'!E42+'วันที่ 10'!E42+'วันที่11'!E42+'วันที่12'!E42+'วันที่13'!E43+'วันที่ 14'!E42+'วันที่ 15'!E42+'วันที่ 16'!E42+'วันที่ 17'!E42+'วันที่ 18'!E42+'วันที่ 19'!E42+'วันที่ 20'!E42+'วันที่ 21'!E42+'วันที่ 22'!E42+'วันที่ 23'!E42+'วันที่ 24'!E42+'วันที่ 25'!E42+'วันที่ 26'!E42+'วันที่ 27'!E42+'วันที่ 28'!E42+'วันที่ 29'!E42+'วันที่ 30'!E42+'วันที่ 31'!E42 -> 0 | D43: ='วันที่ 1'!F43+'วันที่ 2 '!F42+'วันที่ 3'!F42+'วันที่ 4'!F42+'วันที่ 5'!F42+'วันที่ 6'!F42+'วันที่ 7'!F42+'วันที่ 8'!F42+'วันที่ 9'!F42+'วันที่ 10'!F42+'วันที่11'!F42+'วันที่12'!F42+'วันที่13'!F43+'วันที่ 14'!F42+'วันที่ 15'!F42+'วันที่ 16'!F42+'วันที่ 17'!F42+'วันที่ 18'!F42+'วันที่ 19'!F42+'วันที่ 20'!F42+'วันที่ 21'!F42+'วันที่ 22'!F42+'วันที่ 23'!F42+'วันที่ 24'!F42+'วันที่ 25'!F42+'วันที่ 26'!F42+'วันที่ 27'!F42+'วันที่ 28'!F42+'วันที่ 29'!F42+'วันที่ 30'!F42+'วันที่ 31'!F42 -> 0 | E43: ='วันที่ 1'!G43+'วันที่ 2 '!G42+'วันที่ 3'!G42+'วันที่ 4'!G42+'วันที่ 5'!G42+'วันที่ 6'!G42+'วันที่ 7'!G42+'วันที่ 8'!G42+'วันที่ 9'!G42+'วันที่ 10'!G42+'วันที่11'!G42+'วันที่12'!G42+'วันที่13'!G43+'วันที่ 14'!G42+'วันที่ 15'!G42+'วันที่ 16'!G42+'วันที่ 17'!G42+'วันที่ 18'!G42+'วันที่ 19'!G42+'วันที่ 20'!G42+'วันที่ 21'!G42+'วันที่ 22'!G42+'วันที่ 23'!G42+'วันที่ 24'!G42+'วันที่ 25'!G42+'วันที่ 26'!G42+'วันที่ 27'!G42+'วันที่ 28'!G42+'วันที่ 29'!G42+'วันที่ 30'!G42+'วันที่ 31'!G42 -> 0 | F43: ='วันที่ 31'!K42 -> 0
A44: 1000211 | B44: ผงปาปริก้า สูตรปาปริก้า 200 กรัม*ถุง | C44: ='วันที่ 1'!E44+'วันที่ 2 '!E43+'วันที่ 3'!E43+'วันที่ 4'!E43+'วันที่ 5'!E43+'วันที่ 6'!E43+'วันที่ 7'!E43+'วันที่ 8'!E43+'วันที่ 9'!E43+'วันที่ 10'!E43+'วันที่11'!E43+'วันที่12'!E43+'วันที่13'!E44+'วันที่ 14'!E43+'วันที่ 15'!E43+'วันที่ 16'!E43+'วันที่ 17'!E43+'วันที่ 18'!E43+'วันที่ 19'!E43+'วันที่ 20'!E43+'วันที่ 21'!E43+'วันที่ 22'!E43+'วันที่ 23'!E43+'วันที่ 24'!E43+'วันที่ 25'!E43+'วันที่ 26'!E43+'วันที่ 27'!E43+'วันที่ 28'!E43+'วันที่ 29'!E43+'วันที่ 30'!E43+'วันที่ 31'!E43 -> 0 | D44: ='วันที่ 1'!F44+'วันที่ 2 '!F43+'วันที่ 3'!F43+'วันที่ 4'!F43+'วันที่ 5'!F43+'วันที่ 6'!F43+'วันที่ 7'!F43+'วันที่ 8'!F43+'วันที่ 9'!F43+'วันที่ 10'!F43+'วันที่11'!F43+'วันที่12'!F43+'วันที่13'!F44+'วันที่ 14'!F43+'วันที่ 15'!F43+'วันที่ 16'!F43+'วันที่ 17'!F43+'วันที่ 18'!F43+'วันที่ 19'!F43+'วันที่ 20'!F43+'วันที่ 21'!F43+'วันที่ 22'!F43+'วันที่ 23'!F43+'วันที่ 24'!F43+'วันที่ 25'!F43+'วันที่ 26'!F43+'วันที่ 27'!F43+'วันที่ 28'!F43+'วันที่ 29'!F43+'วันที่ 30'!F43+'วันที่ 31'!F43 -> 0 | E44: ='วันที่ 1'!G44+'วันที่ 2 '!G43+'วันที่ 3'!G43+'วันที่ 4'!G43+'วันที่ 5'!G43+'วันที่ 6'!G43+'วันที่ 7'!G43+'วันที่ 8'!G43+'วันที่ 9'!G43+'วันที่ 10'!G43+'วันที่11'!G43+'วันที่12'!G43+'วันที่13'!G44+'วันที่ 14'!G43+'วันที่ 15'!G43+'วันที่ 16'!G43+'วันที่ 17'!G43+'วันที่ 18'!G43+'วันที่ 19'!G43+'วันที่ 20'!G43+'วันที่ 21'!G43+'วันที่ 22'!G43+'วันที่ 23'!G43+'วันที่ 24'!G43+'วันที่ 25'!G43+'วันที่ 26'!G43+'วันที่ 27'!G43+'วันที่ 28'!G43+'วันที่ 29'!G43+'วันที่ 30'!G43+'วันที่ 31'!G43 -> 0 | F44: ='วันที่ 31'!K43 -> 1
A45: 1050007 | B45: น้ำตาลกรวด ตราไร่ทิพย์ 500กรัม | C45: ='วันที่ 1'!E45+'วันที่ 2 '!E44+'วันที่ 3'!E44+'วันที่ 4'!E44+'วันที่ 5'!E44+'วันที่ 6'!E44+'วันที่ 7'!E44+'วันที่ 8'!E44+'วันที่ 9'!E44+'วันที่ 10'!E44+'วันที่11'!E44+'วันที่12'!E44+'วันที่13'!E45+'วันที่ 14'!E44+'วันที่ 15'!E44+'วันที่ 16'!E44+'วันที่ 17'!E44+'วันที่ 18'!E44+'วันที่ 19'!E44+'วันที่ 20'!E44+'วันที่ 21'!E44+'วันที่ 22'!E44+'วันที่ 23'!E44+'วันที่ 24'!E44+'วันที่ 25'!E44+'วันที่ 26'!E44+'วันที่ 27'!E44+'วันที่ 28'!E44+'วันที่ 29'!E44+'วันที่ 30'!E44+'วันที่ 31'!E44 -> 0 | D45: ='วันที่ 1'!F45+'วันที่ 2 '!F44+'วันที่ 3'!F44+'วันที่ 4'!F44+'วันที่ 5'!F44+'วันที่ 6'!F44+'วันที่ 7'!F44+'วันที่ 8'!F44+'วันที่ 9'!F44+'วันที่ 10'!F44+'วันที่11'!F44+'วันที่12'!F44+'วันที่13'!F45+'วันที่ 14'!F44+'วันที่ 15'!F44+'วันที่ 16'!F44+'วันที่ 17'!F44+'วันที่ 18'!F44+'วันที่ 19'!F44+'วันที่ 20'!F44+'วันที่ 21'!F44+'วันที่ 22'!F44+'วันที่ 23'!F44+'วันที่ 24'!F44+'วันที่ 25'!F44+'วันที่ 26'!F44+'วันที่ 27'!F44+'วันที่ 28'!F44+'วันที่ 29'!F44+'วันที่ 30'!F44+'วันที่ 31'!F44 -> 0 | E45: ='วันที่ 1'!G45+'วันที่ 2 '!G44+'วันที่ 3'!G44+'วันที่ 4'!G44+'วันที่ 5'!G44+'วันที่ 6'!G44+'วันที่ 7'!G44+'วันที่ 8'!G44+'วันที่ 9'!G44+'วันที่ 10'!G44+'วันที่11'!G44+'วันที่12'!G44+'วันที่13'!G45+'วันที่ 14'!G44+'วันที่ 15'!G44+'วันที่ 16'!G44+'วันที่ 17'!G44+'วันที่ 18'!G44+'วันที่ 19'!G44+'วันที่ 20'!G44+'วันที่ 21'!G44+'วันที่ 22'!G44+'วันที่ 23'!G44+'วันที่ 24'!G44+'วันที่ 25'!G44+'วันที่ 26'!G44+'วันที่ 27'!G44+'วันที่ 28'!G44+'วันที่ 29'!G44+'วันที่ 30'!G44+'วันที่ 31'!G44 -> 0 | F45: ='วันที่ 31'!K44 -> 3
A46: 1400036 | B46: แพคติน 500 กรัม | C46: ='วันที่ 1'!E46+'วันที่ 2 '!E45+'วันที่ 3'!E45+'วันที่ 4'!E45+'วันที่ 5'!E45+'วันที่ 6'!E45+'วันที่ 7'!E45+'วันที่ 8'!E45+'วันที่ 9'!E45+'วันที่ 10'!E45+'วันที่11'!E45+'วันที่12'!E45+'วันที่13'!E46+'วันที่ 14'!E45+'วันที่ 15'!E45+'วันที่ 16'!E45+'วันที่ 17'!E45+'วันที่ 18'!E45+'วันที่ 19'!E45+'วันที่ 20'!E45+'วันที่ 21'!E45+'วันที่ 22'!E45+'วันที่ 23'!E45+'วันที่ 24'!E45+'วันที่ 25'!E45+'วันที่ 26'!E45+'วันที่ 27'!E45+'วันที่ 28'!E45+'วันที่ 29'!E45+'วันที่ 30'!E45+'วันที่ 31'!E45 -> 0 | D46: ='วันที่ 1'!F46+'วันที่ 2 '!F45+'วันที่ 3'!F45+'วันที่ 4'!F45+'วันที่ 5'!F45+'วันที่ 6'!F45+'วันที่ 7'!F45+'วันที่ 8'!F45+'วันที่ 9'!F45+'วันที่ 10'!F45+'วันที่11'!F45+'วันที่12'!F45+'วันที่13'!F46+'วันที่ 14'!F45+'วันที่ 15'!F45+'วันที่ 16'!F45+'วันที่ 17'!F45+'วันที่ 18'!F45+'วันที่ 19'!F45+'วันที่ 20'!F45+'วันที่ 21'!F45+'วันที่ 22'!F45+'วันที่ 23'!F45+'วันที่ 24'!F45+'วันที่ 25'!F45+'วันที่ 26'!F45+'วันที่ 27'!F45+'วันที่ 28'!F45+'วันที่ 29'!F45+'วันที่ 30'!F45+'วันที่ 31'!F45 -> 0 | E46: ='วันที่ 1'!G46+'วันที่ 2 '!G45+'วันที่ 3'!G45+'วันที่ 4'!G45+'วันที่ 5'!G45+'วันที่ 6'!G45+'วันที่ 7'!G45+'วันที่ 8'!G45+'วันที่ 9'!G45+'วันที่ 10'!G45+'วันที่11'!G45+'วันที่12'!G45+'วันที่13'!G46+'วันที่ 14'!G45+'วันที่ 15'!G45+'วันที่ 16'!G45+'วันที่ 17'!G45+'วันที่ 18'!G45+'วันที่ 19'!G45+'วันที่ 20'!G45+'วันที่ 21'!G45+'วันที่ 22'!G45+'วันที่ 23'!G45+'วันที่ 24'!G45+'วันที่ 25'!G45+'วันที่ 26'!G45+'วันที่ 27'!G45+'วันที่ 28'!G45+'วันที่ 29'!G45+'วันที่ 30'!G45+'วันที่ 31'!G45 -> 0 | F46: ='วันที่ 31'!K45 -> 3
A47: 1000209 | B47: คิคโคแมน ซอสถั่วเหลือง 3 ล. | C47: ='วันที่ 1'!E47+'วันที่ 2 '!E46+'วันที่ 3'!E46+'วันที่ 4'!E46+'วันที่ 5'!E46+'วันที่ 6'!E46+'วันที่ 7'!E46+'วันที่ 8'!E46+'วันที่ 9'!E46+'วันที่ 10'!E46+'วันที่11'!E46+'วันที่12'!E46+'วันที่13'!E47+'วันที่ 14'!E46+'วันที่ 15'!E46+'วันที่ 16'!E46+'วันที่ 17'!E46+'วันที่ 18'!E46+'วันที่ 19'!E46+'วันที่ 20'!E46+'วันที่ 21'!E46+'วันที่ 22'!E46+'วันที่ 23'!E46+'วันที่ 24'!E46+'วันที่ 25'!E46+'วันที่ 26'!E46+'วันที่ 27'!E46+'วันที่ 28'!E46+'วันที่ 29'!E46+'วันที่ 30'!E46+'วันที่ 31'!E46 -> 0 | D47: ='วันที่ 1'!F47+'วันที่ 2 '!F46+'วันที่ 3'!F46+'วันที่ 4'!F46+'วันที่ 5'!F46+'วันที่ 6'!F46+'วันที่ 7'!F46+'วันที่ 8'!F46+'วันที่ 9'!F46+'วันที่ 10'!F46+'วันที่11'!F46+'วันที่12'!F46+'วันที่13'!F47+'วันที่ 14'!F46+'วันที่ 15'!F46+'วันที่ 16'!F46+'วันที่ 17'!F46+'วันที่ 18'!F46+'วันที่ 19'!F46+'วันที่ 20'!F46+'วันที่ 21'!F46+'วันที่ 22'!F46+'วันที่ 23'!F46+'วันที่ 24'!F46+'วันที่ 25'!F46+'วันที่ 26'!F46+'วันที่ 27'!F46+'วันที่ 28'!F46+'วันที่ 29'!F46+'วันที่ 30'!F46+'วันที่ 31'!F46 -> 0 | E47: ='วันที่ 1'!G47+'วันที่ 2 '!G46+'วันที่ 3'!G46+'วันที่ 4'!G46+'วันที่ 5'!G46+'วันที่ 6'!G46+'วันที่ 7'!G46+'วันที่ 8'!G46+'วันที่ 9'!G46+'วันที่ 10'!G46+'วันที่11'!G46+'วันที่12'!G46+'วันที่13'!G47+'วันที่ 14'!G46+'วันที่ 15'!G46+'วันที่ 16'!G46+'วันที่ 17'!G46+'วันที่ 18'!G46+'วันที่ 19'!G46+'วันที่ 20'!G46+'วันที่ 21'!G46+'วันที่ 22'!G46+'วันที่ 23'!G46+'วันที่ 24'!G46+'วันที่ 25'!G46+'วันที่ 26'!G46+'วันที่ 27'!G46+'วันที่ 28'!G46+'วันที่ 29'!G46+'วันที่ 30'!G46+'วันที่ 31'!G46 -> 0 | F47: ='วันที่ 31'!K46 -> 2
A48: 1000181 | B48: ซอส โกชูจัง แฮชานเดิล ซอสพริกเกาหลี 1 กก | C48: ='วันที่ 1'!E48+'วันที่ 2 '!E47+'วันที่ 3'!E47+'วันที่ 4'!E47+'วันที่ 5'!E47+'วันที่ 6'!E47+'วันที่ 7'!E47+'วันที่ 8'!E47+'วันที่ 9'!E47+'วันที่ 10'!E47+'วันที่11'!E47+'วันที่12'!E47+'วันที่13'!E48+'วันที่ 14'!E47+'วันที่ 15'!E47+'วันที่ 16'!E47+'วันที่ 17'!E47+'วันที่ 18'!E47+'วันที่ 19'!E47+'วันที่ 20'!E47+'วันที่ 21'!E47+'วันที่ 22'!E47+'วันที่ 23'!E47+'วันที่ 24'!E47+'วันที่ 25'!E47+'วันที่ 26'!E47+'วันที่ 27'!E47+'วันที่ 28'!E47+'วันที่ 29'!E47+'วันที่ 30'!E47+'วันที่ 31'!E47 -> 0 | D48: ='วันที่ 1'!F48+'วันที่ 2 '!F47+'วันที่ 3'!F47+'วันที่ 4'!F47+'วันที่ 5'!F47+'วันที่ 6'!F47+'วันที่ 7'!F47+'วันที่ 8'!F47+'วันที่ 9'!F47+'วันที่ 10'!F47+'วันที่11'!F47+'วันที่12'!F47+'วันที่13'!F48+'วันที่ 14'!F47+'วันที่ 15'!F47+'วันที่ 16'!F47+'วันที่ 17'!F47+'วันที่ 18'!F47+'วันที่ 19'!F47+'วันที่ 20'!F47+'วันที่ 21'!F47+'วันที่ 22'!F47+'วันที่ 23'!F47+'วันที่ 24'!F47+'วันที่ 25'!F47+'วันที่ 26'!F47+'วันที่ 27'!F47+'วันที่ 28'!F47+'วันที่ 29'!F47+'วันที่ 30'!F47+'วันที่ 31'!F47 -> 0 | E48: ='วันที่ 1'!G48+'วันที่ 2 '!G47+'วันที่ 3'!G47+'วันที่ 4'!G47+'วันที่ 5'!G47+'วันที่ 6'!G47+'วันที่ 7'!G47+'วันที่ 8'!G47+'วันที่ 9'!G47+'วันที่ 10'!G47+'วันที่11'!G47+'วันที่12'!G47+'วันที่13'!G48+'วันที่ 14'!G47+'วันที่ 15'!G47+'วันที่ 16'!G47+'วันที่ 17'!G47+'วันที่ 18'!G47+'วันที่ 19'!G47+'วันที่ 20'!G47+'วันที่ 21'!G47+'วันที่ 22'!G47+'วันที่ 23'!G47+'วันที่ 24'!G47+'วันที่ 25'!G47+'วันที่ 26'!G47+'วันที่ 27'!G47+'วันที่ 28'!G47+'วันที่ 29'!G47+'วันที่ 30'!G47+'วันที่ 31'!G47 -> 0 | F48: ='วันที่ 31'!K47 -> 3
... A102: 1390041 | B102: เส้นหมี่ขาว 2700 กรัม*แพ็ค | C102: ='วันที่ 1'!E102+'วันที่ 2 '!E101+'วันที่ 3'!E101+'วันที่ 4'!E101+'วันที่ 5'!E101+'วันที่ 6'!E101+'วันที่ 7'!E101+'วันที่ 8'!E101+'วันที่ 9'!E101+'วันที่ 10'!E101+'วันที่11'!E101+'วันที่12'!E101+'วันที่13'!E102+'วันที่ 14'!E101+'วันที่ 15'!E101+'วันที่ 16'!E101+'วันที่ 17'!E101+'วันที่ 18'!E101+'วันที่ 19'!E101+'วันที่ 20'!E101+'วันที่ 21'!E101+'วันที่ 22'!E101+'วันที่ 23'!E101+'วันที่ 24'!E101+'วันที่ 25'!E101+'วันที่ 26'!E101+'วันที่ 27'!E101+'วันที่ 28'!E101+'วันที่ 29'!E101+'วันที่ 30'!E101+'วันที่ 31'!E101 -> 0 | D102: ='วันที่ 1'!F102+'วันที่ 2 '!F101+'วันที่ 3'!F101+'วันที่ 4'!F101+'วันที่ 5'!F101+'วันที่ 6'!F101+'วันที่ 7'!F101+'วันที่ 8'!F101+'วันที่ 9'!F101+'วันที่ 10'!F101+'วันที่11'!F101+'วันที่12'!F101+'วันที่13'!F102+'วันที่ 14'!F101+'วันที่ 15'!F101+'วันที่ 16'!F101+'วันที่ 17'!F101+'วันที่ 18'!F101+'วันที่ 19'!F101+'วันที่ 20'!F101+'วันที่ 21'!F101+'วันที่ 22'!F101+'วันที่ 23'!F101+'วันที่ 24'!F101+'วันที่ 25'!F101+'วันที่ 26'!F101+'วันที่ 27'!F101+'วันที่ 28'!F101+'วันที่ 29'!F101+'วันที่ 30'!F101+'วันที่ 31'!F101 -> 0 | E102: ='วันที่ 1'!G102+'วันที่ 2 '!G101+'วันที่ 3'!G101+'วันที่ 4'!G101+'วันที่ 5'!G101+'วันที่ 6'!G101+'วันที่ 7'!G101+'วันที่ 8'!G101+'วันที่ 9'!G101+'วันที่ 10'!G101+'วันที่11'!G101+'วันที่12'!G101+'วันที่13'!G102+'วันที่ 14'!G101+'วันที่ 15'!G101+'วันที่ 16'!G101+'วันที่ 17'!G101+'วันที่ 18'!G101+'วันที่ 19'!G101+'วันที่ 20'!G101+'วันที่ 21'!G101+'วันที่ 22'!G101+'วันที่ 23'!G101+'วันที่ 24'!G101+'วันที่ 25'!G101+'วันที่ 26'!G101+'วันที่ 27'!G101+'วันที่ 28'!G101+'วันที่ 29'!G101+'วันที่ 30'!G101+'วันที่ 31'!G101 -> 0 | F102: ='วันที่ 31'!K101 -> 1
A103: 1390057 | B103: พาสต้า เฟตตูชินีไข่ 1กก. ขั้นต่ำ5ถุง | C103: ='วันที่ 1'!E103+'วันที่ 2 '!E102+'วันที่ 3'!E102+'วันที่ 4'!E102+'วันที่ 5'!E102+'วันที่ 6'!E102+'วันที่ 7'!E102+'วันที่ 8'!E102+'วันที่ 9'!E102+'วันที่ 10'!E102+'วันที่11'!E102+'วันที่12'!E102+'วันที่13'!E103+'วันที่ 14'!E102+'วันที่ 15'!E102+'วันที่ 16'!E102+'วันที่ 17'!E102+'วันที่ 18'!E102+'วันที่ 19'!E102+'วันที่ 20'!E102+'วันที่ 21'!E102+'วันที่ 22'!E102+'วันที่ 23'!E102+'วันที่ 24'!E102+'วันที่ 25'!E102+'วันที่ 26'!E102+'วันที่ 27'!E102+'วันที่ 28'!E102+'วันที่ 29'!E102+'วันที่ 30'!E102+'วันที่ 31'!E102 -> 0 | D103: ='วันที่ 1'!F103+'วันที่ 2 '!F102+'วันที่ 3'!F102+'วันที่ 4'!F102+'วันที่ 5'!F102+'วันที่ 6'!F102+'วันที่ 7'!F102+'วันที่ 8'!F102+'วันที่ 9'!F102+'วันที่ 10'!F102+'วันที่11'!F102+'วันที่12'!F102+'วันที่13'!F103+'วันที่ 14'!F102+'วันที่ 15'!F102+'วันที่ 16'!F102+'วันที่ 17'!F102+'วันที่ 18'!F102+'วันที่ 19'!F102+'วันที่ 20'!F102+'วันที่ 21'!F102+'วันที่ 22'!F102+'วันที่ 23'!F102+'วันที่ 24'!F102+'วันที่ 25'!F102+'วันที่ 26'!F102+'วันที่ 27'!F102+'วันที่ 28'!F102+'วันที่ 29'!F102+'วันที่ 30'!F102+'วันที่ 31'!F102 -> 0 | E103: ='วันที่ 1'!G103+'วันที่ 2 '!G102+'วันที่ 3'!G102+'วันที่ 4'!G102+'วันที่ 5'!G102+'วันที่ 6'!G102+'วันที่ 7'!G102+'วันที่ 8'!G102+'วันที่ 9'!G102+'วันที่ 10'!G102+'วันที่11'!G102+'วันที่12'!G102+'วันที่13'!G103+'วันที่ 14'!G102+'วันที่ 15'!G102+'วันที่ 16'!G102+'วันที่ 17'!G102+'วันที่ 18'!G102+'วันที่ 19'!G102+'วันที่ 20'!G102+'วันที่ 21'!G102+'วันที่ 22'!G102+'วันที่ 23'!G102+'วันที่ 24'!G102+'วันที่ 25'!G102+'วันที่ 26'!G102+'วันที่ 27'!G102+'วันที่ 28'!G102+'วันที่ 29'!G102+'วันที่ 30'!G102+'วันที่ 31'!G102 -> 0 | F103: ='วันที่ 31'!K102 -> 2 | G103: รวมได้
A104: 1390080 | B104: พาสต้าริกาโตเน่ไข่ 1กก.*แพ็ค ขั้นต่ำ5ถุง | C104: ='วันที่ 1'!E104+'วันที่ 2 '!E103+'วันที่ 3'!E103+'วันที่ 4'!E103+'วันที่ 5'!E103+'วันที่ 6'!E103+'วันที่ 7'!E103+'วันที่ 8'!E103+'วันที่ 9'!E103+'วันที่ 10'!E103+'วันที่11'!E103+'วันที่12'!E103+'วันที่13'!E104+'วันที่ 14'!E103+'วันที่ 15'!E103+'วันที่ 16'!E103+'วันที่ 17'!E103+'วันที่ 18'!E103+'วันที่ 19'!E103+'วันที่ 20'!E103+'วันที่ 21'!E103+'วันที่ 22'!E103+'วันที่ 23'!E103+'วันที่ 24'!E103+'วันที่ 25'!E103+'วันที่ 26'!E103+'วันที่ 27'!E103+'วันที่ 28'!E103+'วันที่ 29'!E103+'วันที่ 30'!E103+'วันที่ 31'!E103 -> 0 | D104: ='วันที่ 1'!F104+'วันที่ 2 '!F103+'วันที่ 3'!F103+'วันที่ 4'!F103+'วันที่ 5'!F103+'วันที่ 6'!F103+'วันที่ 7'!F103+'วันที่ 8'!F103+'วันที่ 9'!F103+'วันที่ 10'!F103+'วันที่11'!F103+'วันที่12'!F103+'วันที่13'!F104+'วันที่ 14'!F103+'วันที่ 15'!F103+'วันที่ 16'!F103+'วันที่ 17'!F103+'วันที่ 18'!F103+'วันที่ 19'!F103+'วันที่ 20'!F103+'วันที่ 21'!F103+'วันที่ 22'!F103+'วันที่ 23'!F103+'วันที่ 24'!F103+'วันที่ 25'!F103+'วันที่ 26'!F103+'วันที่ 27'!F103+'วันที่ 28'!F103+'วันที่ 29'!F103+'วันที่ 30'!F103+'วันที่ 31'!F103 -> 0 | E104: ='วันที่ 1'!G104+'วันที่ 2 '!G103+'วันที่ 3'!G103+'วันที่ 4'!G103+'วันที่ 5'!G103+'วันที่ 6'!G103+'วันที่ 7'!G103+'วันที่ 8'!G103+'วันที่ 9'!G103+'วันที่ 10'!G103+'วันที่11'!G103+'วันที่12'!G103+'วันที่13'!G104+'วันที่ 14'!G103+'วันที่ 15'!G103+'วันที่ 16'!G103+'วันที่ 17'!G103+'วันที่ 18'!G103+'วันที่ 19'!G103+'วันที่ 20'!G103+'วันที่ 21'!G103+'วันที่ 22'!G103+'วันที่ 23'!G103+'วันที่ 24'!G103+'วันที่ 25'!G103+'วันที่ 26'!G103+'วันที่ 27'!G103+'วันที่ 28'!G103+'วันที่ 29'!G103+'วันที่ 30'!G103+'วันที่ 31'!G103 -> 0 | F104: ='วันที่ 31'!K103 -> 3 | G104: รวมได้
A105: 1390047 | B105: มักกะโรนีข้องอ 1 กก. ขั้นต่ำ5ถุง | C105: ='วันที่ 1'!E105+'วันที่ 2 '!E104+'วันที่ 3'!E104+'วันที่ 4'!E104+'วันที่ 5'!E104+'วันที่ 6'!E104+'วันที่ 7'!E104+'วันที่ 8'!E104+'วันที่ 9'!E104+'วันที่ 10'!E104+'วันที่11'!E104+'วันที่12'!E104+'วันที่13'!E105+'วันที่ 14'!E104+'วันที่ 15'!E104+'วันที่ 16'!E104+'วันที่ 17'!E104+'วันที่ 18'!E104+'วันที่ 19'!E104+'วันที่ 20'!E104+'วันที่ 21'!E104+'วันที่ 22'!E104+'วันที่ 23'!E104+'วันที่ 24'!E104+'วันที่ 25'!E104+'วันที่ 26'!E104+'วันที่ 27'!E104+'วันที่ 28'!E104+'วันที่ 29'!E104+'วันที่ 30'!E104+'วันที่ 31'!E104 -> 0 | D105: ='วันที่ 1'!F105+'วันที่ 2 '!F104+'วันที่ 3'!F104+'วันที่ 4'!F104+'วันที่ 5'!F104+'วันที่ 6'!F104+'วันที่ 7'!F104+'วันที่ 8'!F104+'วันที่ 9'!F104+'วันที่ 10'!F104+'วันที่11'!F104+'วันที่12'!F104+'วันที่13'!F105+'วันที่ 14'!F104+'วันที่ 15'!F104+'วันที่ 16'!F104+'วันที่ 17'!F104+'วันที่ 18'!F104+'วันที่ 19'!F104+'วันที่ 20'!F104+'วันที่ 21'!F104+'วันที่ 22'!F104+'วันที่ 23'!F104+'วันที่ 24'!F104+'วันที่ 25'!F104+'วันที่ 26'!F104+'วันที่ 27'!F104+'วันที่ 28'!F104+'วันที่ 29'!F104+'วันที่ 30'!F104+'วันที่ 31'!F104 -> 0 | E105: ='วันที่ 1'!G105+'วันที่ 2 '!G104+'วันที่ 3'!G104+'วันที่ 4'!G104+'วันที่ 5'!G104+'วันที่ 6'!G104+'วันที่ 7'!G104+'วันที่ 8'!G104+'วันที่ 9'!G104+'วันที่ 10'!G104+'วันที่11'!G104+'วันที่12'!G104+'วันที่13'!G105+'วันที่ 14'!G104+'วันที่ 15'!G104+'วันที่ 16'!G104+'วันที่ 17'!G104+'วันที่ 18'!G104+'วันที่ 19'!G104+'วันที่ 20'!G104+'วันที่ 21'!G104+'วันที่ 22'!G104+'วันที่ 23'!G104+'วันที่ 24'!G104+'วันที่ 25'!G104+'วันที่ 26'!G104+'วันที่ 27'!G104+'วันที่ 28'!G104+'วันที่ 29'!G104+'วันที่ 30'!G104+'วันที่ 31'!G104 -> 1 | F105: ='วันที่ 31'!K104 -> 3 | G105: รวมได้
A106: 1080014 | B106: งาขาว500กรัม | C106: ='วันที่ 1'!E106+'วันที่ 2 '!E105+'วันที่ 3'!E105+'วันที่ 4'!E105+'วันที่ 5'!E105+'วันที่ 6'!E105+'วันที่ 7'!E105+'วันที่ 8'!E105+'วันที่ 9'!E105+'วันที่ 10'!E105+'วันที่11'!E105+'วันที่12'!E105+'วันที่13'!E106+'วันที่ 14'!E105+'วันที่ 15'!E105+'วันที่ 16'!E105+'วันที่ 17'!E105+'วันที่ 18'!E105+'วันที่ 19'!E105+'วันที่ 20'!E105+'วันที่ 21'!E105+'วันที่ 22'!E105+'วันที่ 23'!E105+'วันที่ 24'!E105+'วันที่ 25'!E105+'วันที่ 26'!E105+'วันที่ 27'!E105+'วันที่ 28'!E105+'วันที่ 29'!E105+'วันที่ 30'!E105+'วันที่ 31'!E105 -> 0 | D106: ='วันที่ 1'!F106+'วันที่ 2 '!F105+'วันที่ 3'!F105+'วันที่ 4'!F105+'วันที่ 5'!F105+'วันที่ 6'!F105+'วันที่ 7'!F105+'วันที่ 8'!F105+'วันที่ 9'!F105+'วันที่ 10'!F105+'วันที่11'!F105+'วันที่12'!F105+'วันที่13'!F106+'วันที่ 14'!F105+'วันที่ 15'!F105+'วันที่ 16'!F105+'วันที่ 17'!F105+'วันที่ 18'!F105+'วันที่ 19'!F105+'วันที่ 20'!F105+'วันที่ 21'!F105+'วันที่ 22'!F105+'วันที่ 23'!F105+'วันที่ 24'!F105+'วันที่ 25'!F105+'วันที่ 26'!F105+'วันที่ 27'!F105+'วันที่ 28'!F105+'วันที่ 29'!F105+'วันที่ 30'!F105+'วันที่ 31'!F105 -> 0 | E106: ='วันที่ 1'!G106+'วันที่ 2 '!G105+'วันที่ 3'!G105+'วันที่ 4'!G105+'วันที่ 5'!G105+'วันที่ 6'!G105+'วันที่ 7'!G105+'วันที่ 8'!G105+'วันที่ 9'!G105+'วันที่ 10'!G105+'วันที่11'!G105+'วันที่12'!G105+'วันที่13'!G106+'วันที่ 14'!G105+'วันที่ 15'!G105+'วันที่ 16'!G105+'วันที่ 17'!G105+'วันที่ 18'!G105+'วันที่ 19'!G105+'วันที่ 20'!G105+'วันที่ 21'!G105+'วันที่ 22'!G105+'วันที่ 23'!G105+'วันที่ 24'!G105+'วันที่ 25'!G105+'วันที่ 26'!G105+'วันที่ 27'!G105+'วันที่ 28'!G105+'วันที่ 29'!G105+'วันที่ 30'!G105+'วันที่ 31'!G105 -> 0 | F106: ='วันที่ 31'!K105 -> 0
A107: 1080015 | B107: งาดำ500กรัม | C107: ='วันที่ 1'!E107+'วันที่ 2 '!E106+'วันที่ 3'!E106+'วันที่ 4'!E106+'วันที่ 5'!E106+'วันที่ 6'!E106+'วันที่ 7'!E106+'วันที่ 8'!E106+'วันที่ 9'!E106+'วันที่ 10'!E106+'วันที่11'!E106+'วันที่12'!E106+'วันที่13'!E107+'วันที่ 14'!E106+'วันที่ 15'!E106+'วันที่ 16'!E106+'วันที่ 17'!E106+'วันที่ 18'!E106+'วันที่ 19'!E106+'วันที่ 20'!E106+'วันที่ 21'!E106+'วันที่ 22'!E106+'วันที่ 23'!E106+'วันที่ 24'!E106+'วันที่ 25'!E106+'วันที่ 26'!E106+'วันที่ 27'!E106+'วันที่ 28'!E106+'วันที่ 29'!E106+'วันที่ 30'!E106+'วันที่ 31'!E106 -> 0 | D107: ='วันที่ 1'!F107+'วันที่ 2 '!F106+'วันที่ 3'!F106+'วันที่ 4'!F106+'วันที่ 5'!F106+'วันที่ 6'!F106+'วันที่ 7'!F106+'วันที่ 8'!F106+'วันที่ 9'!F106+'วันที่ 10'!F106+'วันที่11'!F106+'วันที่12'!F106+'วันที่13'!F107+'วันที่ 14'!F106+'วันที่ 15'!F106+'วันที่ 16'!F106+'วันที่ 17'!F106+'วันที่ 18'!F106+'วันที่ 19'!F106+'วันที่ 20'!F106+'วันที่ 21'!F106+'วันที่ 22'!F106+'วันที่ 23'!F106+'วันที่ 24'!F106+'วันที่ 25'!F106+'วันที่ 26'!F106+'วันที่ 27'!F106+'วันที่ 28'!F106+'วันที่ 29'!F106+'วันที่ 30'!F106+'วันที่ 31'!F106 -> 0 | E107: ='วันที่ 1'!G107+'วันที่ 2 '!G106+'วันที่ 3'!G106+'วันที่ 4'!G106+'วันที่ 5'!G106+'วันที่ 6'!G106+'วันที่ 7'!G106+'วันที่ 8'!G106+'วันที่ 9'!G106+'วันที่ 10'!G106+'วันที่11'!G106+'วันที่12'!G106+'วันที่13'!G107+'วันที่ 14'!G106+'วันที่ 15'!G106+'วันที่ 16'!G106+'วันที่ 17'!G106+'วันที่ 18'!G106+'วันที่ 19'!G106+'วันที่ 20'!G106+'วันที่ 21'!G106+'วันที่ 22'!G106+'วันที่ 23'!G106+'วันที่ 24'!G106+'วันที่ 25'!G106+'วันที่ 26'!G106+'วันที่ 27'!G106+'วันที่ 28'!G106+'วันที่ 29'!G106+'วันที่ 30'!G106+'วันที่ 31'!G106 -> 0 | F107: ='วันที่ 31'!K106 -> 2
A108: 1200061 | B108: ข้าวคั่ว 500 กรัม | C108: ='วันที่ 1'!E108+'วันที่ 2 '!E107+'วันที่ 3'!E107+'วันที่ 4'!E107+'วันที่ 5'!E107+'วันที่ 6'!E107+'วันที่ 7'!E107+'วันที่ 8'!E107+'วันที่ 9'!E107+'วันที่ 10'!E107+'วันที่11'!E107+'วันที่12'!E107+'วันที่13'!E108+'วันที่ 14'!E107+'วันที่ 15'!E107+'วันที่ 16'!E107+'วันที่ 17'!E107+'วันที่ 18'!E107+'วันที่ 19'!E107+'วันที่ 20'!E107+'วันที่ 21'!E107+'วันที่ 22'!E107+'วันที่ 23'!E107+'วันที่ 24'!E107+'วันที่ 25'!E107+'วันที่ 26'!E107+'วันที่ 27'!E107+'วันที่ 28'!E107+'วันที่ 29'!E107+'วันที่ 30'!E107+'วันที่ 31'!E107 -> 0 | D108: ='วันที่ 1'!F108+'วันที่ 2 '!F107+'วันที่ 3'!F107+'วันที่ 4'!F107+'วันที่ 5'!F107+'วันที่ 6'!F107+'วันที่ 7'!F107+'วันที่ 8'!F107+'วันที่ 9'!F107+'วันที่ 10'!F107+'วันที่11'!F107+'วันที่12'!F107+'วันที่13'!F108+'วันที่ 14'!F107+'วันที่ 15'!F107+'วันที่ 16'!F107+'วันที่ 17'!F107+'วันที่ 18'!F107+'วันที่ 19'!F107+'วันที่ 20'!F107+'วันที่ 21'!F107+'วันที่ 22'!F107+'วันที่ 23'!F107+'วันที่ 24'!F107+'วันที่ 25'!F107+'วันที่ 26'!F107+'วันที่ 27'!F107+'วันที่ 28'!F107+'วันที่ 29'!F107+'วันที่ 30'!F107+'วันที่ 31'!F107 -> 0 | E108: ='วันที่ 1'!G108+'วันที่ 2 '!G107+'วันที่ 3'!G107+'วันที่ 4'!G107+'วันที่ 5'!G107+'วันที่ 6'!G107+'วันที่ 7'!G107+'วันที่ 8'!G107+'วันที่ 9'!G107+'วันที่ 10'!G107+'วันที่11'!G107+'วันที่12'!G107+'วันที่13'!G108+'วันที่ 14'!G107+'วันที่ 15'!G107+'วันที่ 16'!G107+'วันที่ 17'!G107+'วันที่ 18'!G107+'วันที่ 19'!G107+'วันที่ 20'!G107+'วันที่ 21'!G107+'วันที่ 22'!G107+'วันที่ 23'!G107+'วันที่ 24'!G107+'วันที่ 25'!G107+'วันที่ 26'!G107+'วันที่ 27'!G107+'วันที่ 28'!G107+'วันที่ 29'!G107+'วันที่ 30'!G107+'วันที่ 31'!G107 -> 0 | F108: ='วันที่ 31'!K107 -> 2
A109: 1080018 | B109: พริกป่น (ถุง 500 กรัม) | C109: ='วันที่ 1'!E109+'วันที่ 2 '!E108+'วันที่ 3'!E108+'วันที่ 4'!E108+'วันที่ 5'!E108+'วันที่ 6'!E108+'วันที่ 7'!E108+'วันที่ 8'!E108+'วันที่ 9'!E108+'วันที่ 10'!E108+'วันที่11'!E108+'วันที่12'!E108+'วันที่13'!E109+'วันที่ 14'!E108+'วันที่ 15'!E108+'วันที่ 16'!E108+'วันที่ 17'!E108+'วันที่ 18'!E108+'วันที่ 19'!E108+'วันที่ 20'!E108+'วันที่ 21'!E108+'วันที่ 22'!E108+'วันที่ 23'!E108+'วันที่ 24'!E108+'วันที่ 25'!E108+'วันที่ 26'!E108+'วันที่ 27'!E108+'วันที่ 28'!E108+'วันที่ 29'!E108+'วันที่ 30'!E108+'วันที่ 31'!E108 -> 0 | D109: ='วันที่ 1'!F109+'วันที่ 2 '!F108+'วันที่ 3'!F108+'วันที่ 4'!F108+'วันที่ 5'!F108+'วันที่ 6'!F108+'วันที่ 7'!F108+'วันที่ 8'!F108+'วันที่ 9'!F108+'วันที่ 10'!F108+'วันที่11'!F108+'วันที่12'!F108+'วันที่13'!F109+'วันที่ 14'!F108+'วันที่ 15'!F108+'วันที่ 16'!F108+'วันที่ 17'!F108+'วันที่ 18'!F108+'วันที่ 19'!F108+'วันที่ 20'!F108+'วันที่ 21'!F108+'วันที่ 22'!F108+'วันที่ 23'!F108+'วันที่ 24'!F108+'วันที่ 25'!F108+'วันที่ 26'!F108+'วันที่ 27'!F108+'วันที่ 28'!F108+'วันที่ 29'!F108+'วันที่ 30'!F108+'วันที่ 31'!F108 -> 0 | E109: ='วันที่ 1'!G109+'วันที่ 2 '!G108+'วันที่ 3'!G108+'วันที่ 4'!G108+'วันที่ 5'!G108+'วันที่ 6'!G108+'วันที่ 7'!G108+'วันที่ 8'!G108+'วันที่ 9'!G108+'วันที่ 10'!G108+'วันที่11'!G108+'วันที่12'!G108+'วันที่13'!G109+'วันที่ 14'!G108+'วันที่ 15'!G108+'วันที่ 16'!G108+'วันที่ 17'!G108+'วันที่ 18'!G108+'วันที่ 19'!G108+'วันที่ 20'!G108+'วันที่ 21'!G108+'วันที่ 22'!G108+'วันที่ 23'!G108+'วันที่ 24'!G108+'วันที่ 25'!G108+'วันที่ 26'!G108+'วันที่ 27'!G108+'วันที่ 28'!G108+'วันที่ 29'!G108+'วันที่ 30'!G108+'วันที่ 31'!G108 -> 0 | F109: ='วันที่ 31'!K108 -> 1
A110: 1200091 | B110: ลูกเดือย 500 กรัม *ห่อ | C110: ='วันที่ 1'!E110+'วันที่ 2 '!E109+'วันที่ 3'!E109+'วันที่ 4'!E109+'วันที่ 5'!E109+'วันที่ 6'!E109+'วันที่ 7'!E109+'วันที่ 8'!E109+'วันที่ 9'!E109+'วันที่ 10'!E109+'วันที่11'!E109+'วันที่12'!E109+'วันที่13'!E110+'วันที่ 14'!E109+'วันที่ 15'!E109+'วันที่ 16'!E109+'วันที่ 17'!E109+'วันที่ 18'!E109+'วันที่ 19'!E109+'วันที่ 20'!E109+'วันที่ 21'!E109+'วันที่ 22'!E109+'วันที่ 23'!E109+'วันที่ 24'!E109+'วันที่ 25'!E109+'วันที่ 26'!E109+'วันที่ 27'!E109+'วันที่ 28'!E109+'วันที่ 29'!E109+'วันที่ 30'!E109+'วันที่ 31'!E109 -> 0 | D110: ='วันที่ 1'!F110+'วันที่ 2 '!F109+'วันที่ 3'!F109+'วันที่ 4'!F109+'วันที่ 5'!F109+'วันที่ 6'!F109+'วันที่ 7'!F109+'วันที่ 8'!F109+'วันที่ 9'!F109+'วันที่ 10'!F109+'วันที่11'!F109+'วันที่12'!F109+'วันที่13'!F110+'วันที่ 14'!F109+'วันที่ 15'!F109+'วันที่ 16'!F109+'วันที่ 17'!F109+'วันที่ 18'!F109+'วันที่ 19'!F109+'วันที่ 20'!F109+'วันที่ 21'!F109+'วันที่ 22'!F109+'วันที่ 23'!F109+'วันที่ 24'!F109+'วันที่ 25'!F109+'วันที่ 26'!F109+'วันที่ 27'!F109+'วันที่ 28'!F109+'วันที่ 29'!F109+'วันที่ 30'!F109+'วันที่ 31'!F109 -> 0 | E110: ='วันที่ 1'!G110+'วันที่ 2 '!G109+'วันที่ 3'!G109+'วันที่ 4'!G109+'วันที่ 5'!G109+'วันที่ 6'!G109+'วันที่ 7'!G109+'วันที่ 8'!G109+'วันที่ 9'!G109+'วันที่ 10'!G109+'วันที่11'!G109+'วันที่12'!G109+'วันที่13'!G110+'วันที่ 14'!G109+'วันที่ 15'!G109+'วันที่ 16'!G109+'วันที่ 17'!G109+'วันที่ 18'!G109+'วันที่ 19'!G109+'วันที่ 20'!G109+'วันที่ 21'!G109+'วันที่ 22'!G109+'วันที่ 23'!G109+'วันที่ 24'!G109+'วันที่ 25'!G109+'วันที่ 26'!G109+'วันที่ 27'!G109+'วันที่ 28'!G109+'วันที่ 29'!G109+'วันที่ 30'!G109+'วันที่ 31'!G109 -> 0 | F110: ='วันที่ 31'!K109 -> 1
A112: 1080009 | B112: พริกไทยดำเม็ด 500 กรัม | C112: ='วันที่ 1'!E112+'วันที่ 2 '!E111+'วันที่ 3'!E111+'วันที่ 4'!E111+'วันที่ 5'!E111+'วันที่ 6'!E111+'วันที่ 7'!E111+'วันที่ 8'!E111+'วันที่ 9'!E111+'วันที่ 10'!E111+'วันที่11'!E111+'วันที่12'!E111+'วันที่13'!E112+'วันที่ 14'!E111+'วันที่ 15'!E111+'วันที่ 16'!E111+'วันที่ 17'!E111+'วันที่ 18'!E111+'วันที่ 19'!E111+'วันที่ 20'!E111+'วันที่ 21'!E111+'วันที่ 22'!E111+'วันที่ 23'!E111+'วันที่ 24'!E111+'วันที่ 25'!E111+'วันที่ 26'!E111+'วันที่ 27'!E111+'วันที่ 28'!E111+'วันที่ 29'!E111+'วันที่ 30'!E111+'วันที่ 31'!E111 -> 0 | D112: ='วันที่ 1'!F112+'วันที่ 2 '!F111+'วันที่ 3'!F111+'วันที่ 4'!F111+'วันที่ 5'!F111+'วันที่ 6'!F111+'วันที่ 7'!F111+'วันที่ 8'!F111+'วันที่ 9'!F111+'วันที่ 10'!F111+'วันที่11'!F111+'วันที่12'!F111+'วันที่13'!F112+'วันที่ 14'!F111+'วันที่ 15'!F111+'วันที่ 16'!F111+'วันที่ 17'!F111+'วันที่ 18'!F111+'วันที่ 19'!F111+'วันที่ 20'!F111+'วันที่ 21'!F111+'วันที่ 22'!F111+'วันที่ 23'!F111+'วันที่ 24'!F111+'วันที่ 25'!F111+'วันที่ 26'!F111+'วันที่ 27'!F111+'วันที่ 28'!F111+'วันที่ 29'!F111+'วันที่ 30'!F111+'วันที่ 31'!F111 -> 0 | E112: ='วันที่ 1'!G112+'วันที่ 2 '!G111+'วันที่ 3'!G111+'วันที่ 4'!G111+'วันที่ 5'!G111+'วันที่ 6'!G111+'วันที่ 7'!G111+'วันที่ 8'!G111+'วันที่ 9'!G111+'วันที่ 10'!G111+'วันที่11'!G111+'วันที่12'!G111+'วันที่13'!G112+'วันที่ 14'!G111+'วันที่ 15'!G111+'วันที่ 16'!G111+'วันที่ 17'!G111+'วันที่ 18'!G111+'วันที่ 19'!G111+'วันที่ 20'!G111+'วันที่ 21'!G111+'วันที่ 22'!G111+'วันที่ 23'!G111+'วันที่ 24'!G111+'วันที่ 25'!G111+'วันที่ 26'!G111+'วันที่ 27'!G111+'วันที่ 28'!G111+'วันที่ 29'!G111+'วันที่ 30'!G111+'วันที่ 31'!G111 -> 0 | F112: ='วันที่ 31'!K111 -> 0
...

Sheet วันที่ 1
A1: Stock
A3: Code | B3: รายการ | C3: ยอดยกมาจากวันที่ 31 | D3: รับเข้า | E3: department | H3: Onstock | I3: Par stock | J3: Status | K3: ยอดยกไป
E4: Breakfast | F4: Canteen | G4: A la carte
A5: ='Monthly Summary'!A5 -> 1000005 | B5: ='Monthly Summary'!B5 -> เกลือ ปรุงทิพย์ 1000 กรัม | C5: 8 | H5: =(C5+D5)-E5-F5-G5 -> 8 | I5: 10 | J5: =IF(H5<I5,"Need to Order",IF(H5>=I5," ")) -> Need to Order | K5: =H5 -> 8
A6: ='Monthly Summary'!A6 -> 1000018 | B6: ='Monthly Summary'!B6 -> เต้าเจี้ยวสูตร 1 เด็กสมบูรณ์ 800 มล.*3 | C6: 1 | H6: =C6+D6-E6-F6-G6 -> 1 | I6: 2 | J6: =IF(H6<I6,"Need to Order",IF(H6>=I6," ")) -> Need to Order | K6: =H6 -> 1
A7: ='Monthly Summary'!A7 -> 1000015 | B7: ='Monthly Summary'!B7 -> ซีอิ้วดำสูตร 5 เด็กสมบูรณ์ 940ml. | C7: 2 | H7: =C7+D7-E7-F7-G7 -> 2 | I7: 4 | J7: =IF(H7<I7,"Need to Order",IF(H7>=I7," ")) -> Need to Order | K7: =H7 -> 2
A8: ='Monthly Summary'!A8 -> 1000025 | B8: ='Monthly Summary'!B8 -> น้ำมันน้ำพริกเผา ฉั่วฮะเส็ง 700 ml. | C8: 3 | H8: =C8+D8-E8-F8-G8 -> 3 | I8: 3 | J8: =IF(H8<I8,"Need to Order",IF(H8>=I8," ")) | K8: =H8 -> 3
A9: ='Monthly Summary'!A9 -> 1000022 | B9: ='Monthly Summary'!B9 -> น้ำพริกเผาฉัวฮะเส็ง 2700g. | C9: 2 | H9: =C9+D9-E9-F9-G9 -> 2 | I9: 3 | J9: =IF(H9<I9,"Need to Order",IF(H9>=I9," ")) -> Need to Order | K9: =H9 -> 2
A10: ='Monthly Summary'!A10 -> 1000057 | B10: ='Monthly Summary'!B10 -> ผงปรุงรส อาหารญี่ปุ่น ฮอนดาชิ 1กก. | C10: 3 | H10: =C10+D10-E10-F10-G10 -> 3 | I10: 6 | J10: =IF(H10<I10,"Need to Order",IF(H10>=I10," ")) -> Need to Order | K10: =H10 -> 3
A11: 1000214 | B11: ซอสมะเขือเทศเข้มข้น ตราไมก้า 560 กรัม/กระป๋อง | C11: 1 | H11: =C11+D11-E11-F11-G11 -> 1 | I11: 2 | J11: =IF(H11<I11,"Need to Order",IF(H11>=I11," ")) -> Need to Order | K11: =H11 -> 1
A12: ='Monthly Summary'!A12 -> 1010017 | B12: ='Monthly Summary'!B12 -> ปลากระป๋อง | C12: 78 | H12: =C12+D12-E12-F12-G12 -> 78 | I12: 135 | J12: =IF(H12<I12,"Need to Order",IF(H12>=I12," ")) -> Need to Order | K12: =H12 -> 78
A13: ='Monthly Summary'!A13 -> 1010033 | B13: ='Monthly Summary'!B13 -> ปลาทูน่าในน้ำมันตราซีเล็คทูน่า 1800 กรัม*1 | C13: 3 | H13: =C13+D13-E13-F13-G13 -> 3 | I13: 6 | J13: =IF(H13<I13,"Need to Order",IF(H13>=I13," ")) -> Need to Order | K13: =H13 -> 3
A14: ='Monthly Summary'!A14 -> 1050003 | B14: ='Monthly Summary'!B14 -> น้ำตาลทรายขาวมิตรผล 1 กก.*ถุง | C14: 63 | H14: =C14+D14-E14-F14-G14 -> 63 | I14: 110 | J14: =IF(H14<I14,"Need to Order",IF(H14>=I14," ")) -> Need to Order | K14: =H14 -> 63
